Workbook

Sheet README
A1: DATRE CORPORATION LIMITED - MIS FINALISATION TEMPLATE (HO ACCOUNTS)
A2: Financial year 2026-27 | Rs. in Lacs
A4: FLOW
A5: 1. Factory feeds monthly P&L data -> sheet IN_PLF (column for the month).
A6: 2. Factory / Costing feeds product-wise contribution rows -> sheet IN_Contrib (append rows; FY and Month text must match, e.g. 2026-27 / October).
A7: 3. HO Accounts enters ledger items and adjustments -> sheet IN_HO (admin, salary, adjustments, MT statistics, collections).
A8: 4. Sheet MIS recalculates automatically (same layout as the published 'P&L for the year 2026-27 (Based on Sales)').
A9: 5. Sheet CONTRIB_SUM summarises contribution data by month / customer and cross-checks against MIS.
A10: 6. Sheet CHECK compares MIS output with the published Sept'26 MIS (Apr-Sep) - use as proof of the formula logic. Clear/ignore from Oct'26 onward.
A11: 7. Sheet PY_COMPARE holds the prior-year statistics from the published MIS; FY26-27 rows link live to MIS.
A13: COLOUR CODE
A14: Blue font = hard-coded input. Black = formula. Yellow fill = item to confirm/explain (see notes).
... A36: Paste factory PL figures into the month column of IN_PLF > append contribution rows in IN_Contrib > fill IN_HO for the month > review MIS and CONTRIB_SUM > clear yellow flags.

Sheet MIS
A1: DATRE CORPORATION LIMITED
A2: PROFIT AND LOSS ACCOUNT for the year 2026-27 (Based on Sales)
A3: Rs. In Lacs | R3: Average/Month
A5: PARTICULARS | B5: APR'26 | C5: MAY'26 | D5: JUN'26 | E5: 1st Qtr | F5: JUL'26 | G5: AUG'26 | H5: SEP'26 | I5: 2nd Qtr | J5: OCT'26 | K5: NOV'26 | L5: DEC'26 | M5: 3rd Qtr | N5: JAN'27 | O5: FEB'27 | P5: MAR'27 | Q5: 4th Qtr | R5: Total
A6: Turnover :
A7: Sales Domestic (incl GST) | B7: =B9+B8 -> 150.43 | C7: =C9+C8 -> 183.09 | D7: =D9+D8 -> 252.08 | E7: =SUM(B7:D7) -> 585.6 | F7: =F9+F8 -> 326.82 | G7: =G9+G8 -> 271.68 | H7: =H9+H8 -> 257.64 | I7: =SUM(F7:H7) -> 856.14 | J7: =J9+J8 -> 0 | K7: =K9+K8 -> 0 | L7: =L9+L8 -> 0 | M7: =SUM(J7:L7) -> 0 | N7: =N9+N8 -> 0 | O7: =O9+O8 -> 0 | P7: =P9+P8 -> 0 | Q7: =SUM(N7:P7) -> 0 | R7: =E7+I7+M7+Q7 -> 1441.74
A8: Less GST | B8: =ROUND(B9*IN_HO!C5,2) -> 22.95 | C8: =ROUND(C9*IN_HO!D5,2) -> 27.93 | D8: =ROUND(D9*IN_HO!E5,2) -> 38.45 | E8: =SUM(B8:D8) -> 89.33 | F8: =ROUND(F9*IN_HO!F5,2) -> 49.85 | G8: =ROUND(G9*IN_HO!G5,2) -> 41.44 | H8: =ROUND(H9*IN_HO!H5,2) -> 39.3 | I8: =SUM(F8:H8) -> 130.59 | J8: =ROUND(J9*IN_HO!I5,2) -> 0 | K8: =ROUND(K9*IN_HO!J5,2) -> 0 | L8: =ROUND(L9*IN_HO!K5,2) -> 0 | M8: =SUM(J8:L8) -> 0 | N8: =ROUND(N9*IN_HO!L5,2) -> 0 | O8: =ROUND(O9*IN_HO!M5,2) -> 0 | P8: =ROUND(P9*IN_HO!N5,2) -> 0 | Q8: =SUM(N8:P8) -> 0 | R8: =E8+I8+M8+Q8 -> 219.92
A9: Sales Domestic (ex GST) | B9: =IN_PLF!C38 -> 127.48 | C9: =IN_PLF!D38 -> 155.16 | D9: =IN_PLF!E38 -> 213.63 | E9: =SUM(B9:D9) -> 496.27 | F9: =IN_PLF!F38 -> 276.97 | G9: =IN_PLF!G38 -> 230.24 | H9: =IN_PLF!H38 -> 218.34 | I9: =SUM(F9:H9) -> 725.55 | J9: =IN_PLF!I38 -> 0 | K9: =IN_PLF!J38 -> 0 | L9: =IN_PLF!K38 -> 0 | M9: =SUM(J9:L9) -> 0 | N9: =IN_PLF!L38 -> 0 | O9: =IN_PLF!M38 -> 0 | P9: =IN_PLF!N38 -> 0 | Q9: =SUM(N9:P9) -> 0 | R9: =E9+I9+M9+Q9 -> 1221.82
A10: Less: Sales Return | B10: =IN_PLF!C49 -> 0 | C10: =IN_PLF!D49 -> 4.86 | D10: =IN_PLF!E49 -> 7.15 | E10: =SUM(B10:D10) -> 12.01 | F10: =IN_PLF!F49 -> 1.35 | G10: =IN_PLF!G49 -> 1 | H10: =IN_PLF!H49 -> 0.56 | I10: =SUM(F10:H10) -> 2.91 | J10: =IN_PLF!I49 -> 0 | K10: =IN_PLF!J49 -> 0 | L10: =IN_PLF!K49 -> 0 | M10: =SUM(J10:L10) -> 0 | N10: =IN_PLF!L49 -> 0 | O10: =IN_PLF!M49 -> 0 | P10: =IN_PLF!N49 -> 0 | Q10: =SUM(N10:P10) -> 0 | R10: =E10+I10+M10+Q10 -> 14.92
A11: Net Sales | B11: =B9-B10 -> 127.48 | C11: =C9-C10 -> 150.3 | D11: =D9-D10 -> 206.48 | E11: =SUM(B11:D11) -> 484.26 | F11: =F9-F10 -> 275.62 | G11: =G9-G10 -> 229.24 | H11: =H9-H10 -> 217.78 | I11: =SUM(F11:H11) -> 722.64 | J11: =J9-J10 -> 0 | K11: =K9-K10 -> 0 | L11: =L9-L10 -> 0 | M11: =SUM(J11:L11) -> 0 | N11: =N9-N10 -> 0 | O11: =O9-O10 -> 0 | P11: =P9-P10 -> 0 | Q11: =SUM(N11:P11) -> 0 | R11: =E11+I11+M11+Q11 -> 1206.9
A12: Other Business Income/Sales | B12: =IN_PLF!C43-IN_HO!C13 -> 0 | C12: =IN_PLF!D43-IN_HO!D13 -> 1.5 | D12: =IN_PLF!E43-IN_HO!E13 -> 0 | E12: =SUM(B12:D12) -> 1.5 | F12: =IN_PLF!F43-IN_HO!F13 -> 0 | G12: =IN_PLF!G43-IN_HO!G13 -> 2.5 | H12: =IN_PLF!H43-IN_HO!H13 -> 4.8 | I12: =SUM(F12:H12) -> 7.3 | J12: =IN_PLF!I43-IN_HO!I13 -> 0 | K12: =IN_PLF!J43-IN_HO!J13 -> 0 | L12: =IN_PLF!K43-IN_HO!K13 -> 0 | M12: =SUM(J12:L12) -> 0 | N12: =IN_PLF!L43-IN_HO!L13 -> 0 | O12: =IN_PLF!M43-IN_HO!M13 -> 0 | P12: =IN_PLF!N43-IN_HO!N13 -> 0 | Q12: =SUM(N12:P12) -> 0 | R12: =E12+I12+M12+Q12 -> 8.8
A13: Stock of Return Goods (Valued at Sales Price) | B13: =IN_PLF!C35 -> -15.08 | C13: =IN_PLF!D35 -> -3.56 | D13: =IN_PLF!E35 -> -4.02 | E13: =SUM(B13:D13) -> -22.66 | F13: =IN_PLF!F35 -> -3.79 | G13: =IN_PLF!G35 -> 1 | H13: =IN_PLF!H35 -> 0.56 | I13: =SUM(F13:H13) -> -2.23 | J13: =IN_PLF!I35 -> 0 | K13: =IN_PLF!J35 -> 0 | L13: =IN_PLF!K35 -> 0 | M13: =SUM(J13:L13) -> 0 | N13: =IN_PLF!L35 -> 0 | O13: =IN_PLF!M35 -> 0 | P13: =IN_PLF!N35 -> 0 | Q13: =SUM(N13:P13) -> 0 | R13: =E13+I13+M13+Q13 -> -24.89
A14: Net turnover for contribution | B14: =B11+B12+B13 -> 112.4 | C14: =C11+C12+C13 -> 148.24 | D14: =D11+D12+D13 -> 202.46 | E14: =SUM(B14:D14) -> 463.1 | F14: =F11+F12+F13 -> 271.83 | G14: =G11+G12+G13 -> 232.74 | H14: =H11+H12+H13 -> 223.14 | I14: =SUM(F14:H14) -> 727.71 | J14: =J11+J12+J13 -> 0 | K14: =K11+K12+K13 -> 0 | L14: =L11+L12+L13 -> 0 | M14: =SUM(J14:L14) -> 0 | N14: =N11+N12+N13 -> 0 | O14: =O11+O12+O13 -> 0 | P14: =P11+P12+P13 -> 0 | Q14: =SUM(N14:P14) -> 0 | R14: =E14+I14+M14+Q14 -> 1190.81
A15: Direct Expenditure (Variable Costs):
A16: Material Consumed-Direct & Indirect | B16: =IN_PLF!C5+IN_HO!C8 -> 47.91 | C16: =IN_PLF!D5+IN_HO!D8 -> 159.27 | D16: =IN_PLF!E5+IN_HO!E8 -> 153.67 | E16: =SUM(B16:D16) -> 360.85 | F16: =IN_PLF!F5+IN_HO!F8 -> 160.21 | G16: =IN_PLF!G5+IN_HO!G8 -> 109.64 | H16: =IN_PLF!H5+IN_HO!H8 -> 174.02 | I16: =SUM(F16:H16) -> 443.87 | J16: =IN_PLF!I5+IN_HO!I8 -> 0 | K16: =IN_PLF!J5+IN_HO!J8 -> 0 | L16: =IN_PLF!K5+IN_HO!K8 -> 0 | M16: =SUM(J16:L16) -> 0 | N16: =IN_PLF!L5+IN_HO!L8 -> 0 | O16: =IN_PLF!M5+IN_HO!M8 -> 0 | P16: =IN_PLF!N5+IN_HO!N8 -> 0 | Q16: =SUM(N16:P16) -> 0 | R16: =E16+I16+M16+Q16 -> 804.72
A17: (Increase)/Decrease in Stock | B17: =-IN_PLF!C32+IN_HO!C9 -> 31.72 | C17: =-IN_PLF!D32+IN_HO!D9 -> -71.63 | D17: =-IN_PLF!E32+IN_HO!E9 -> -32.47 | E17: =SUM(B17:D17) -> -72.38 | F17: =-IN_PLF!F32+IN_HO!F9 -> 22.62 | G17: =-IN_PLF!G32+IN_HO!G9 -> 43.89 | H17: =-IN_PLF!H32+IN_HO!H9 -> -48.76 | I17: =SUM(F17:H17) -> 17.75 | J17: =-IN_PLF!I32+IN_HO!I9 -> 0 | K17: =-IN_PLF!J32+IN_HO!J9 -> 0 | L17: =-IN_PLF!K32+IN_HO!K9 -> 0 | M17: =SUM(J17:L17) -> 0 | N17: =-IN_PLF!L32+IN_HO!L9 -> 0 | O17: =-IN_PLF!M32+IN_HO!M9 -> 0 | P17: =-IN_PLF!N32+IN_HO!N9 -> 0 | Q17: =SUM(N17:P17) -> 0 | R17: =E17+I17+M17+Q17 -> -54.63
A18: Manufacturing Overheads:
A19: - Power & Fuel (Variable part) | B19: =IN_PLF!C19+IN_PLF!C20+IN_HO!C10 -> 10.61 | C19: =IN_PLF!D19+IN_PLF!D20+IN_HO!D10 -> 15.14 | D19: =IN_PLF!E19+IN_PLF!E20+IN_HO!E10 -> 17.79 | E19: =SUM(B19:D19) -> 43.54 | F19: =IN_PLF!F19+IN_PLF!F20+IN_HO!F10 -> 18.01 | G19: =IN_PLF!G19+IN_PLF!G20+IN_HO!G10 -> 17.14 | H19: =IN_PLF!H19+IN_PLF!H20+IN_HO!H10 -> 18.37 | I19: =SUM(F19:H19) -> 53.52 | J19: =IN_PLF!I19+IN_PLF!I20+IN_HO!I10 -> 0 | K19: =IN_PLF!J19+IN_PLF!J20+IN_HO!J10 -> 0 | L19: =IN_PLF!K19+IN_PLF!K20+IN_HO!K10 -> 0 | M19: =SUM(J19:L19) -> 0 | N19: =IN_PLF!L19+IN_PLF!L20+IN_HO!L10 -> 0 | O19: =IN_PLF!M19+IN_PLF!M20+IN_HO!M10 -> 0 | P19: =IN_PLF!N19+IN_PLF!N20+IN_HO!N10 -> 0 | Q19: =SUM(N19:P19) -> 0 | R19: =E19+I19+M19+Q19 -> 97.06
A20: - Job-work Charges | B20: =IN_PLF!C9+IN_HO!C11 -> 9.1 | C20: =IN_PLF!D9+IN_HO!D11 -> 9.61 | D20: =IN_PLF!E9+IN_HO!E11 -> 12.19 | E20: =SUM(B20:D20) -> 30.9 | F20: =IN_PLF!F9+IN_HO!F11 -> 12.73 | G20: =IN_PLF!G9+IN_HO!G11 -> 11.56 | H20: =IN_PLF!H9+IN_HO!H11 -> 12.67 | I20: =SUM(F20:H20) -> 36.96 | J20: =IN_PLF!I9+IN_HO!I11 -> 0 | K20: =IN_PLF!J9+IN_HO!J11 -> 0 | L20: =IN_PLF!K9+IN_HO!K11 -> 0 | M20: =SUM(J20:L20) -> 0 | N20: =IN_PLF!L9+IN_HO!L11 -> 0 | O20: =IN_PLF!M9+IN_HO!M11 -> 0 | P20: =IN_PLF!N9+IN_HO!N11 -> 0 | Q20: =SUM(N20:P20) -> 0 | R20: =E20+I20+M20+Q20 -> 67.86
A21: Total Net Variable Costs | B21: =B16+B17+B19+B20 -> 99.34 | C21: =C16+C17+C19+C20 -> 112.39 | D21: =D16+D17+D19+D20 -> 151.18 | E21: =SUM(B21:D21) -> 362.91 | F21: =F16+F17+F19+F20 -> 213.57 | G21: =G16+G17+G19+G20 -> 182.23 | H21: =H16+H17+H19+H20 -> 156.3 | I21: =SUM(F21:H21) -> 552.1 | J21: =J16+J17+J19+J20 -> 0 | K21: =K16+K17+K19+K20 -> 0 | L21: =L16+L17+L19+L20 -> 0 | M21: =SUM(J21:L21) -> 0 | N21: =N16+N17+N19+N20 -> 0 | O21: =O16+O17+O19+O20 -> 0 | P21: =P16+P17+P19+P20 -> 0 | Q21: =SUM(N21:P21) -> 0 | R21: =E21+I21+M21+Q21 -> 915.01
A22: Contributions | B22: =B14-B21 -> 13.06 | C22: =C14-C21 -> 35.85 | D22: =D14-D21 -> 51.28 | E22: =SUM(B22:D22) -> 100.19 | F22: =F14-F21 -> 58.26 | G22: =G14-G21 -> 50.51 | H22: =H14-H21 -> 66.84 | I22: =SUM(F22:H22) -> 175.61 | J22: =J14-J21 -> 0 | K22: =K14-K21 -> 0 | L22: =L14-L21 -> 0 | M22: =SUM(J22:L22) -> 0 | N22: =N14-N21 -> 0 | O22: =O14-O21 -> 0 | P22: =P14-P21 -> 0 | Q22: =SUM(N22:P22) -> 0 | R22: =E22+I22+M22+Q22 -> 275.8
A24: Indirect Expenses (Fixed):
A25: Administrative Expenses | B25: =IN_HO!C16 -> 3.21 | C25: =IN_HO!D16 -> 4.13 | D25: =IN_HO!E16 -> 4.5 | E25: =SUM(B25:D25) -> 11.84 | F25: =IN_HO!F16 -> 7.52 | G25: =IN_HO!G16 -> 6.07 | H25: =IN_HO!H16 -> 7.13 | I25: =SUM(F25:H25) -> 20.72 | J25: =IN_HO!I16 -> 0 | K25: =IN_HO!J16 -> 0 | L25: =IN_HO!K16 -> 0 | M25: =SUM(J25:L25) -> 0 | N25: =IN_HO!L16 -> 0 | O25: =IN_HO!M16 -> 0 | P25: =IN_HO!N16 -> 0 | Q25: =SUM(N25:P25) -> 0 | R25: =E25+I25+M25+Q25 -> 32.56
A26: Material Consumed - Repair & maintt. | B26: =IN_PLF!C21 -> 1.38 | C26: =IN_PLF!D21 -> 2.28 | D26: =IN_PLF!E21 -> 2.31 | E26: =SUM(B26:D26) -> 5.97 | F26: =IN_PLF!F21 -> 3.41 | G26: =IN_PLF!G21 -> 2.28 | H26: =IN_PLF!H21 -> 1.97 | I26: =SUM(F26:H26) -> 7.66 | J26: =IN_PLF!I21 -> 0 | K26: =IN_PLF!J21 -> 0 | L26: =IN_PLF!K21 -> 0 | M26: =SUM(J26:L26) -> 0 | N26: =IN_PLF!L21 -> 0 | O26: =IN_PLF!M21 -> 0 | P26: =IN_PLF!N21 -> 0 | Q26: =SUM(N26:P26) -> 0 | R26: =E26+I26+M26+Q26 -> 13.63
A27: Other Manufacturing Overhead (Fixed) | B27: =IN_PLF!C22-IN_HO!C12 -> 4.62 | C27: =IN_PLF!D22-IN_HO!D12 -> 5.7 | D27: =IN_PLF!E22-IN_HO!E12 -> 5.93 | E27: =SUM(B27:D27) -> 16.25 | F27: =IN_PLF!F22-IN_HO!F12 -> 5.44 | G27: =IN_PLF!G22-IN_HO!G12 -> 4.71 | H27: =IN_PLF!H22-IN_HO!H12 -> 6.92 | I27: =SUM(F27:H27) -> 17.07 | J27: =IN_PLF!I22-IN_HO!I12 -> 0 | K27: =IN_PLF!J22-IN_HO!J12 -> 0 | L27: =IN_PLF!K22-IN_HO!K12 -> 0 | M27: =SUM(J27:L27) -> 0 | N27: =IN_PLF!L22-IN_HO!L12 -> 0 | O27: =IN_PLF!M22-IN_HO!M12 -> 0 | P27: =IN_PLF!N22-IN_HO!N12 -> 0 | Q27: =SUM(N27:P27) -> 0 | R27: =E27+I27+M27+Q27 -> 33.32
A28: Salary & Wages | B28: =IN_HO!C17 -> 15.91 | C28: =IN_HO!D17 -> 12.37 | D28: =IN_HO!E17 -> 14.85 | E28: =SUM(B28:D28) -> 43.13 | F28: =IN_HO!F17 -> 16.85 | G28: =IN_HO!G17 -> 15.87 | H28: =IN_HO!H17 -> 16.61 | I28: =SUM(F28:H28) -> 49.33 | J28: =IN_HO!I17 -> 0 | K28: =IN_HO!J17 -> 0 | L28: =IN_HO!K17 -> 0 | M28: =SUM(J28:L28) -> 0 | N28: =IN_HO!L17 -> 0 | O28: =IN_HO!M17 -> 0 | P28: =IN_HO!N17 -> 0 | Q28: =SUM(N28:P28) -> 0 | R28: =E28+I28+M28+Q28 -> 92.46
A29: - Power & Fuel (Fixed Part - Max Demand Charges) | B29: =IN_PLF!C18 -> 5.58 | C29: =IN_PLF!D18 -> 5.88 | D29: =IN_PLF!E18 -> 5.56 | E29: =SUM(B29:D29) -> 17.02 | F29: =IN_PLF!F18 -> 5.53 | G29: =IN_PLF!G18 -> 7.21 | H29: =IN_PLF!H18 -> 7.25 | I29: =SUM(F29:H29) -> 19.99 | J29: =IN_PLF!I18 -> 0 | K29: =IN_PLF!J18 -> 0 | L29: =IN_PLF!K18 -> 0 | M29: =SUM(J29:L29) -> 0 | N29: =IN_PLF!L18 -> 0 | O29: =IN_PLF!M18 -> 0 | P29: =IN_PLF!N18 -> 0 | Q29: =SUM(N29:P29) -> 0 | R29: =E29+I29+M29+Q29 -> 37.01
A30: Selling Expenses | B30: =IN_HO!C12 -> 0 | C30: =IN_HO!D12 -> 0 | D30: =IN_HO!E12 -> 0 | E30: =SUM(B30:D30) -> 0 | F30: =IN_HO!F12 -> 0 | G30: =IN_HO!G12 -> 0 | H30: =IN_HO!H12 -> 3.22 | I30: =SUM(F30:H30) -> 3.22 | J30: =IN_HO!I12 -> 0 | K30: =IN_HO!J12 -> 0 | L30: =IN_HO!K12 -> 0 | M30: =SUM(J30:L30) -> 0 | N30: =IN_HO!L12 -> 0 | O30: =IN_HO!M12 -> 0 | P30: =IN_HO!N12 -> 0 | Q30: =SUM(N30:P30) -> 0 | R30: =E30+I30+M30+Q30 -> 3.22
A31: Total Fixed Costs | B31: =SUM(B25:B30) -> 30.7 | C31: =SUM(C25:C30) -> 30.36 | D31: =SUM(D25:D30) -> 33.15 | E31: =SUM(B31:D31) -> 94.21 | F31: =SUM(F25:F30) -> 38.75 | G31: =SUM(G25:G30) -> 36.14 | H31: =SUM(H25:H30) -> 43.1 | I31: =SUM(F31:H31) -> 117.99 | J31: =SUM(J25:J30) -> 0 | K31: =SUM(K25:K30) -> 0 | L31: =SUM(L25:L30) -> 0 | M31: =SUM(J31:L31) -> 0 | N31: =SUM(N25:N30) -> 0 | O31: =SUM(O25:O30) -> 0 | P31: =SUM(P25:P30) -> 0 | Q31: =SUM(N31:P31) -> 0 | R31: =E31+I31+M31+Q31 -> 212.2
A32: NET PROFIT FROM OPERATIONS | B32: =B22-B31 -> -17.64 | C32: =C22-C31 -> 5.49 | D32: =D22-D31 -> 18.13 | E32: =SUM(B32:D32) -> 5.98 | F32: =F22-F31 -> 19.51 | G32: =G22-G31 -> 14.37 | H32: =H22-H31 -> 23.74 | I32: =SUM(F32:H32) -> 57.62 | J32: =J22-J31 -> 0 | K32: =K22-K31 -> 0 | L32: =L22-L31 -> 0 | M32: =SUM(J32:L32) -> 0 | N32: =N22-N31 -> 0 | O32: =O22-O31 -> 0 | P32: =P22-P31 -> 0 | Q32: =SUM(N32:P32) -> 0 | R32: =E32+I32+M32+Q32 -> 63.6
A33: Less: Deferred Revenue Expenses | B33: =IN_HO!C18 -> 0 | C33: =IN_HO!D18 -> 0 | D33: =IN_HO!E18 -> 0 | E33: =SUM(B33:D33) -> 0 | F33: =IN_HO!F18 -> 0 | G33: =IN_HO!G18 -> 0 | H33: =IN_HO!H18 -> 0 | I33: =SUM(F33:H33) -> 0 | J33: =IN_HO!I18 -> 0 | K33: =IN_HO!J18 -> 0 | L33: =IN_HO!K18 -> 0 | M33: =SUM(J33:L33) -> 0 | N33: =IN_HO!L18 -> 0 | O33: =IN_HO!M18 -> 0 | P33: =IN_HO!N18 -> 0 | Q33: =SUM(N33:P33) -> 0 | R33: =E33+I33+M33+Q33 -> 0
A34: Less: Other Non-Operating Expenses | B34: =IN_HO!C19 -> 0 | C34: =IN_HO!D19 -> 0 | D34: =IN_HO!E19 -> 0 | E34: =SUM(B34:D34) -> 0 | F34: =IN_HO!F19 -> 0 | G34: =IN_HO!G19 -> 0 | H34: =IN_HO!H19 -> 0 | I34: =SUM(F34:H34) -> 0 | J34: =IN_HO!I19 -> 0 | K34: =IN_HO!J19 -> 0 | L34: =IN_HO!K19 -> 0 | M34: =SUM(J34:L34) -> 0 | N34: =IN_HO!L19 -> 0 | O34: =IN_HO!M19 -> 0 | P34: =IN_HO!N19 -> 0 | Q34: =SUM(N34:P34) -> 0 | R34: =E34+I34+M34+Q34 -> 0
A35: Profit after Deferred Revenue Expenditure | B35: =B32-B33-B34 -> -17.64 | C35: =C32-C33-C34 -> 5.49 | D35: =D32-D33-D34 -> 18.13 | E35: =SUM(B35:D35) -> 5.98 | F35: =F32-F33-F34 -> 19.51 | G35: =G32-G33-G34 -> 14.37 | H35: =H32-H33-H34 -> 23.74 | I35: =SUM(F35:H35) -> 57.62 | J35: =J32-J33-J34 -> 0 | K35: =K32-K33-K34 -> 0 | L35: =L32-L33-L34 -> 0 | M35: =SUM(J35:L35) -> 0 | N35: =N32-N33-N34 -> 0 | O35: =O32-O33-O34 -> 0 | P35: =P32-P33-P34 -> 0 | Q35: =SUM(N35:P35) -> 0 | R35: =E35+I35+M35+Q35 -> 63.6
A36: Net Income from Storage Facility Service Charges | B36: =IN_PLF!C45+IN_HO!C13 -> 6.89 | C36: =IN_PLF!D45+IN_HO!D13 -> 6.89 | D36: =IN_PLF!E45+IN_HO!E13 -> 6.89 | E36: =SUM(B36:D36) -> 20.67 | F36: =IN_PLF!F45+IN_HO!F13 -> 6.95 | G36: =IN_PLF!G45+IN_HO!G13 -> 7.91 | H36: =IN_PLF!H45+IN_HO!H13 -> 7.39 | I36: =SUM(F36:H36) -> 22.25 | J36: =IN_PLF!I45+IN_HO!I13 -> 0 | K36: =IN_PLF!J45+IN_HO!J13 -> 0 | L36: =IN_PLF!K45+IN_HO!K13 -> 0 | M36: =SUM(J36:L36) -> 0 | N36: =IN_PLF!L45+IN_HO!L13 -> 0 | O36: =IN_PLF!M45+IN_HO!M13 -> 0 | P36: =IN_PLF!N45+IN_HO!N13 -> 0 | Q36: =SUM(N36:P36) -> 0 | R36: =E36+I36+M36+Q36 -> 42.92
A37: EBITDA | B37: =B35+B36 -> -10.75 | C37: =C35+C36 -> 12.38 | D37: =D35+D36 -> 25.02 | E37: =SUM(B37:D37) -> 26.65 | F37: =F35+F36 -> 26.46 | G37: =G35+G36 -> 22.28 | H37: =H35+H36 -> 31.13 | I37: =SUM(F37:H37) -> 79.87 | J37: =J35+J36 -> 0 | K37: =K35+K36 -> 0 | L37: =L35+L36 -> 0 | M37: =SUM(J37:L37) -> 0 | N37: =N35+N36 -> 0 | O37: =O35+O36 -> 0 | P37: =P35+P36 -> 0 | Q37: =SUM(N37:P37) -> 0 | R37: =E37+I37+M37+Q37 -> 106.52
A38: Depreciation | B38: =IN_HO!C20 -> 0 | C38: =IN_HO!D20 -> 0 | D38: =IN_HO!E20 -> 0 | E38: =SUM(B38:D38) -> 0 | F38: =IN_HO!F20 -> 0 | G38: =IN_HO!G20 -> 0 | H38: =IN_HO!H20 -> 0 | I38: =SUM(F38:H38) -> 0 | J38: =IN_HO!I20 -> 0 | K38: =IN_HO!J20 -> 0 | L38: =IN_HO!K20 -> 0 | M38: =SUM(J38:L38) -> 0 | N38: =IN_HO!L20 -> 0 | O38: =IN_HO!M20 -> 0 | P38: =IN_HO!N20 -> 0 | Q38: =SUM(N38:P38) -> 0 | R38: =E38+I38+M38+Q38 -> 0
A39: Interest | B39: =IN_HO!C21 -> 0 | C39: =IN_HO!D21 -> 0 | D39: =IN_HO!E21 -> 0 | E39: =SUM(B39:D39) -> 0 | F39: =IN_HO!F21 -> 0 | G39: =IN_HO!G21 -> 0 | H39: =IN_HO!H21 -> 0 | I39: =SUM(F39:H39) -> 0 | J39: =IN_HO!I21 -> 0 | K39: =IN_HO!J21 -> 0 | L39: =IN_HO!K21 -> 0 | M39: =SUM(J39:L39) -> 0 | N39: =IN_HO!L21 -> 0 | O39: =IN_HO!M21 -> 0 | P39: =IN_HO!N21 -> 0 | Q39: =SUM(N39:P39) -> 0 | R39: =E39+I39+M39+Q39 -> 0
A40: PBT 2026-27 | B40: =B37-B38-B39 -> -10.75 | C40: =C37-C38-C39 -> 12.38 | D40: =D37-D38-D39 -> 25.02 | E40: =SUM(B40:D40) -> 26.65 | F40: =F37-F38-F39 -> 26.46 | G40: =G37-G38-G39 -> 22.28 | H40: =H37-H38-H39 -> 31.13 | I40: =SUM(F40:H40) -> 79.87 | J40: =J37-J38-J39 -> 0 | K40: =K37-K38-K39 -> 0 | L40: =L37-L38-L39 -> 0 | M40: =SUM(J40:L40) -> 0 | N40: =N37-N38-N39 -> 0 | O40: =O37-O38-O39 -> 0 | P40: =P37-P38-P39 -> 0 | Q40: =SUM(N40:P40) -> 0 | R40: =E40+I40+M40+Q40 -> 106.52
A43: STATISTICS - 2026-27
A44: PARTICULARS | B44: APR'26 | C44: MAY'26 | D44: JUN'26 | E44: 1st Qtr | F44: JUL'26 | G44: AUG'26 | H44: SEP'26 | I44: 2nd Qtr | J44: OCT'26 | K44: NOV'26 | L44: DEC'26 | M44: 3rd Qtr | N44: JAN'27 | O44: FEB'27 | P44: MAR'27 | Q44: 4th Qtr | R44: Total | S44: Average/Month
...

Sheet IN_PLF
A1: PL FACTORY DATA - monthly feed from factory (Rs. Lacs)
A3: Sl | B3: Particulars | C3: Apr'26 | D3: May'26 | E3: Jun'26 | F3: Jul'26 | G3: Aug'26 | H3: Sep'26 | I3: Oct'26 | J3: Nov'26 | K3: Dec'26 | L3: Jan'27 | M3: Feb'27 | N3: Mar'27
A5: 1 | B5: Material Consumption: | C5: =SUM(C6:C8) -> 49.71 | D5: =SUM(D6:D8) -> 159.27 | E5: =SUM(E6:E8) -> 151.43 | F5: =SUM(F6:F8) -> 157.21 | G5: =SUM(G6:G8) -> 107.64 | H5: =SUM(H6:H8) -> 171.02 | I5: =SUM(I6:I8) -> 0 | J5: =SUM(J6:J8) -> 0 | ... N5: =SUM(N6:N8) -> 0
B6: Basic RM | C6: 37.43 | D6: 144.29 | E6: 135.24 | F6: 134.88 | G6: 84.93 | H6: 148.59
B7: Consumables | C7: 11.75 | D7: 14.9 | E7: 15.86 | F7: 21.66 | G7: 22.1 | H7: 21.92
B8: Addln. Exp on Purchase | C8: 0.53 | D8: 0.08 | E8: 0.33 | F8: 0.67 | G8: 0.61 | H8: 0.51
A9: 2 | B9: Contractual Prodn Expenses (Job): | C9: =SUM(C10:C16) -> 9.1 | D9: =SUM(D10:D16) -> 9.48 | E9: =SUM(E10:E16) -> 10.12 | F9: =SUM(F10:F16) -> 10.73 | G9: =SUM(G10:G16) -> 9.55 | H9: =SUM(H10:H16) -> 10.67 | I9: =SUM(I10:I16) -> 0 | J9: =SUM(J10:J16) -> 0 | ... N9: =SUM(N10:N16) -> 0
B10: Krishna Enterprise - MLT MLD Etc | C10: 3.76 | D10: 3.95 | E10: 3.87 | F10: 4.5 | G10: 3.54 | H10: 4.43
B11: Rahaman Enterprise QC | C11: 0 | D11: 0 | E11: 0 | F11: 0 | G11: 0 | H11: 0
B12: Krishna Enterprise / Rahaman - FLT | C12: 3.99 | D12: 3.97 | E12: 4.18 | F12: 4.35 | G12: 4.37 | H12: 4.7
B13: Sree Engineering | C13: 0.55 | D13: 0.76 | E13: 0.7 | F13: 0.9 | G13: 0.89 | H13: 0.79
B14: Tapas Samanta & Outside-Inside Machining | C14: 0 | D14: 0 | E14: 0 | F14: 0 | G14: 0 | H14: 0
B15: Outside H/T | C15: 0 | D15: 0 | E15: 0.22 | F15: 0 | G15: 0 | H15: 0
B16: Radiography Charges | C16: 0.8 | D16: 0.8 | E16: 1.15 | F16: 0.98 | G16: 0.75 | H16: 0.75
A17: 3 | B17: Power | C17: =SUM(C18:C20) -> 16.05 | D17: =SUM(D18:D20) -> 21.02 | E17: =SUM(E18:E20) -> 23.34 | F17: =SUM(F18:F20) -> 23.55 | G17: =SUM(G18:G20) -> 24.35 | H17: =SUM(H18:H20) -> 25.62 | I17: =SUM(I18:I20) -> 0 | J17: =SUM(J18:J20) -> 0 | ... N17: =SUM(N18:N20) -> 0
B18: Demand Charges | C18: 5.58 | D18: 5.88 | E18: 5.56 | F18: 5.53 | G18: 7.21 | H18: 7.25
B19: Power Cost - Excl. Demand Charge | C19: 10.47 | D19: 15.14 | E19: 17.78 | F19: 18.02 | G19: 17.14 | H19: 18.37
B20: DG fuel | C20: 0 | D20: 0 | E20: 0 | F20: 0 | G20: 0 | H20: 0
A21: 4 | B21: Consumption for Plant & Mach. Maintenance: | C21: 1.38 | D21: 2.28 | E21: 2.31 | F21: 3.41 | G21: 2.28 | H21: 1.97
A22: 5 | B22: Other Expenses as per trial (Factory): | C22: =SUM(C23:C31) -> 4.62 | D22: =SUM(D23:D31) -> 5.7 | E22: =SUM(E23:E31) -> 5.93 | F22: =SUM(F23:F31) -> 5.44 | G22: =SUM(G23:G31) -> 4.71 | H22: =SUM(H23:H31) -> 10.14 | I22: =SUM(I23:I31) -> 0 | J22: =SUM(J23:J31) -> 0 | ... N22: =SUM(N23:N31) -> 0
B23: Machinery Maintenance - Service | C23: 0.03 | D23: 1.34 | E23: 1.38 | F23: 0.46 | G23: 0.22 | H23: 0.51
B24: Maintenance - Building | C24: 0 | D24: 0 | E24: 0 | F24: 1.38 | G24: 0 | H24: 2.13
B25: Security Exp | C25: 1.46 | D25: 1.5 | E25: 1.45 | F25: 1.55 | G25: 1.46 | H25: 1.46
B26: Manufacturing OH | C26: 3.06 | D26: 2.51 | E26: 2.48 | F26: 2 | G26: 2.98 | H26: 2.77
B27: Selling & Distribution Exp | C27: 0 | D27: 0 | E27: 0 | F27: 0 | G27: 0 | H27: 0
B28: Business Promotion | C28: 0.07 | D28: 0.35 | E28: 0.33 | F28: 0.05 | G28: 0.05 | H28: 0.05
B29: Transport agst Sale | C29: 0 | D29: 0 | E29: 0 | F29: 0 | G29: 0 | H29: 0
B30: Transport sale return | C30: 0 | D30: 0 | E30: 0.29 | F30: 0 | G30: 0 | H30: 3.22
B31: Liquidity damages | C31: 0 | D31: 0 | E31: 0 | F31: 0 | G31: 0 | H31: 0
A32: 6 | B32: Increase(+)/Decrease(-) in Stock (WIP) [as reported by factory] | C32: -31.72 | D32: 71.63 | E32: 32.47 | F32: -22.62 | G32: -40.89 | H32: 48.76
B33: OP WIP | C33: 152.29 | D33: =C34 -> 120.57 | E33: =D34 -> 192.2 | F33: =E34 -> 224.67 | G33: =F34 -> 202.05 | H33: =G34 -> 161.16 | I33: =H34 -> 209.92 | J33: =I34 -> 0 | K33: =J34 -> 0 | ... N33: =M34 -> 0
B34: CL WIP | C34: 120.57 | D34: 192.2 | E34: 224.67 | F34: 202.05 | G34: 161.16 | H34: 209.92
A35: 7 | B35: Increase(+)/Decrease(-) of Stock of Returned Goods [as reported] | C35: -15.08 | D35: -3.56 | E35: -4.02 | F35: -3.79 | G35: 1 | H35: 0.56
B36: OP Stock | C36: 58.66 | D36: =C37 -> 43.58 | E36: =D37 -> 40.03 | F36: =E37 -> 36.01 | G36: =F37 -> 32.22 | H36: =G37 -> 33.22 | I36: =H37 -> 33.78 | J36: =I37 -> 0 | K36: =J37 -> 0 | ... N36: =M37 -> 0
B37: CL Stock | C37: 43.58 | D37: 40.03 | E37: 36.01 | F37: 32.22 | G37: 33.22 | H37: 33.78
A38: 8 | B38: Sale (Fresh & Cus Ret. Goods) for the month: | C38: =SUM(C39:C40) -> 127.48 | D38: =SUM(D39:D40) -> 155.16 | E38: =SUM(E39:E40) -> 213.63 | F38: =SUM(F39:F40) -> 276.97 | G38: =SUM(G39:G40) -> 230.24 | H38: =SUM(H39:H40) -> 218.34 | I38: =SUM(I39:I40) -> 0 | J38: =SUM(J39:J40) -> 0 | ... N38: =SUM(N39:N40) -> 0
B39: a. Actual despatch Made | C39: 127.48 | D39: 90.02 | E39: 278.77 | F39: 276.97 | G39: 230.24 | H39: 218.34
B40: b. Ready to despatch _ Adjustment | C40: 0 | D40: 65.14 | E40: -65.14 | F40: 0 | G40: 0 | H40: 0
A41: 9 | B41: Other Sale / Income | C41: =SUM(C42:C48) -> 6.89 | D41: =SUM(D42:D48) -> 8.39 | E41: =SUM(E42:E48) -> 6.89 | F41: =SUM(F42:F48) -> 6.95 | G41: =SUM(G42:G48) -> 10.41 | H41: =SUM(H42:H48) -> 12.19 | I41: =SUM(I42:I48) -> 0 | J41: =SUM(J42:J48) -> 0 | ... N41: =SUM(N42:N48) -> 0
B42: Foundry return (Unusable) | C42: 0 | D42: 0 | E42: 0 | F42: 0 | G42: 0 | H42: 0
...

Sheet IN_Contrib
A1: CONTRIBUTION DATA - product-wise monthly cost sheet (append new month rows below; keep Year/Month text exact)
A3: Customer | B3: Year | C3: Month | D3: Product | E3: Weight per Casting (Kg) | F3: Pouring (Nos) | G3: Prodn-Pouring (MT) | H3: Rejn In House (Nos) | I3: Destruct. Test (Nos) | J3: Effective Yield % | K3: Melting Raw Mat Cost Rs/kg | L3: Melting Refractories etc Rs/kg | M3: MLD Mat Cost Rs/kg | N3: FTL Mat Cost Rs/kg | O3: Component Rs/kg | P3: Inspn Mat Rs/kg | Q3: Spl Material per Kg | R3: Packg & Painting Rs/kg | S3: Total Material Cost Rs/kg | T3: Other Direct Exp per Kg | U3: Labour Charges Rs/kg | V3: Power Cost (Var) Rs/kg | W3: Total Var Cost Rs/kg | X3: Effective Sale Price Rs/kg | Y3: Contribution Rs/kg | Z3: Customer-wise Contribution Rs L | AA3: Rejn Loss (Exc OH) Rs L | AB3: Loss on Destruct Test Rs L | AC3: Loss of Contribution Rejn & Destr. Rs L | AD3: Rejection MT (calc) | AE3: Destruct Test MT (calc) | AF3: Var Cost check (Mat+Oth+Lab+Pow-Total) | AG3: Contrib/kg check (Sale-Var-Contr)
A4: Tega | B4: 2022-23 | C4: April | D4: RM-22-00587E000-T1 | E4: 18.75 | F4: 6 | G4: 0.11 | J4: 59.61 | K4: 108.92 | L4: 2.21 | M4: 19.55 | N4: 3.9 | O4: 0.45 | P4: 1.5 | R4: 1.1 | S4: 137.63 | T4: 0.9 | U4: 10 | V4: 20.68 | W4: 169.2 | X4: 223.53 | Y4: 54.33 | Z4: 0.06 | AA4: 0 | AB4: 0 | AC4: 0 | AD4: =H4*E4/1000 -> 0 | AE4: =I4*E4/1000 -> 0 | AF4: =ROUND(S4+T4+U4+V4-W4,2) -> 0.01 | AG4: =ROUND(X4-W4-Y4,2) -> 0
A5: Tega | B5: 2022-23 | C5: April | D5: RM-22-00589E000-T1 | E5: 25 | F5: 24 | G5: 0.6 | J5: 63.85 | K5: 108.46 | L5: 2.07 | M5: 19.54 | N5: 3.9 | O5: 0.45 | P5: 1.5 | R5: 1.1 | S5: 137.02 | T5: 0.9 | U5: 10 | V5: 19.89 | W5: 167.81 | X5: 223.53 | Y5: 55.72 | Z5: 0.33 | AA5: 0 | AB5: 0 | AC5: 0 | AD5: =H5*E5/1000 -> 0 | AE5: =I5*E5/1000 -> 0 | AF5: =ROUND(S5+T5+U5+V5-W5,2) -> 0 | AG5: =ROUND(X5-W5-Y5,2) -> 0
A6: Tega | B6: 2022-23 | C6: April | D6: RM-22-01952AN00-T1 | E6: 20.7 | F6: 8 | G6: 0.17 | J6: 59.04 | K6: 108.99 | L6: 2.24 | M6: 18.01 | N6: 3.9 | O6: 0.45 | P6: 1.5 | R6: 1.1 | S6: 136.18 | T6: 0.9 | U6: 10 | V6: 20.79 | W6: 167.87 | X6: 223.53 | Y6: 55.66 | Z6: 0.09 | AA6: 0 | AB6: 0 | AC6: 0 | AD6: =H6*E6/1000 -> 0 | AE6: =I6*E6/1000 -> 0 | AF6: =ROUND(S6+T6+U6+V6-W6,2) -> 0 | AG6: =ROUND(X6-W6-Y6,2) -> 0
A7: Tega | B7: 2022-23 | C7: April | D7: RM-22-01879ON00-T1 | E7: 29.7 | F7: 18 | G7: 0.53 | J7: 60.87 | K7: 108.78 | L7: 2.17 | M7: 15.94 | N7: 3.9 | O7: 0.45 | P7: 1.5 | R7: 1.1 | S7: 133.84 | T7: 0.9 | U7: 10 | V7: 20.43 | W7: 165.17 | X7: 223.53 | Y7: 58.36 | Z7: 0.31 | AA7: 0 | AB7: 0 | AC7: 0 | AD7: =H7*E7/1000 -> 0 | AE7: =I7*E7/1000 -> 0 | AF7: =ROUND(S7+T7+U7+V7-W7,2) -> 0 | AG7: =ROUND(X7-W7-Y7,2) -> 0
A8: Tega | B8: 2022-23 | C8: April | D8: RM-22-02783ON00-T1 | E8: 39.26 | F8: 8 | G8: 0.31 | J8: 64.15 | K8: 108.43 | L8: 2.06 | M8: 13.65 | N8: 3.9 | O8: 0.54 | P8: 1.5 | R8: 1.1 | S8: 131.18 | T8: 0.9 | U8: 10 | V8: 19.84 | W8: 161.92 | X8: 223.53 | Y8: 61.61 | Z8: 0.19 | AA8: 0 | AB8: 0 | AC8: 0 | AD8: =H8*E8/1000 -> 0 | AE8: =I8*E8/1000 -> 0 | AF8: =ROUND(S8+T8+U8+V8-W8,2) -> 0 | AG8: =ROUND(X8-W8-Y8,2) -> 0
A9: Tega | B9: 2022-23 | C9: April | D9: RM-22-07245ON00-T1 | E9: 28.92 | F9: 4 | G9: 0.12 | J9: 63.01 | K9: 108.55 | L9: 2.09 | M9: 16.53 | N9: 3.9 | O9: 0.45 | P9: 1.5 | R9: 1.1 | S9: 134.12 | T9: 0.9 | U9: 10 | V9: 20.04 | W9: 165.06 | X9: 223.53 | Y9: 58.47 | Z9: 0.07 | AA9: 0 | AB9: 0 | AC9: 0 | AD9: =H9*E9/1000 -> 0 | AE9: =I9*E9/1000 -> 0 | AF9: =ROUND(S9+T9+U9+V9-W9,2) -> 0 | AG9: =ROUND(X9-W9-Y9,2) -> 0
A10: Tega | B10: 2022-23 | C10: May | D10: RM-22-00589E000-T1 | E10: 25 | F10: 96 | G10: 2.4 | J10: 63.85 | K10: 123.74 | L10: 2.07 | M10: 19.25 | N10: 3.9 | O10: 0.45 | P10: 1.5 | R10: 1.1 | S10: 152.02 | T10: 0.9 | U10: 10.2 | V10: 18.52 | W10: 181.64 | X10: 223.53 | Y10: 41.89 | Z10: 1.01 | AA10: 0 | AB10: 0 | AC10: 0 | AD10: =H10*E10/1000 -> 0 | AE10: =I10*E10/1000 -> 0 | AF10: =ROUND(S10+T10+U10+V10-W10,2) -> 0 | AG10: =ROUND(X10-W10-Y10,2) -> 0
A11: Tega | B11: 2022-23 | C11: May | D11: RM-22-01952AN00-T1 | E11: 20.7 | F11: 52 | G11: 1.08 | I11: 1 | J11: 59.04 | K11: 124.34 | L11: 2.24 | M11: 17.77 | N11: 3.9 | O11: 0.45 | P11: 1.5 | R11: 1.1 | S11: 151.3 | T11: 0.9 | U11: 10.2 | V11: 19.39 | W11: 181.79 | X11: 223.53 | Y11: 41.74 | Z11: 0.43 | AA11: 0 | AB11: 0.01 | AC11: 0.01 | AD11: =H11*E11/1000 -> 0 | AE11: =I11*E11/1000 -> 0.0207 | AF11: =ROUND(S11+T11+U11+V11-W11,2) -> 0 | AG11: =ROUND(X11-W11-Y11,2) -> 0
A12: Tega | B12: 2022-23 | C12: May | D12: RM-22-06182ON00-T1 | E12: 18 | F12: 1 | G12: 0.02 | J12: 64.17 | K12: 123.71 | L12: 2.06 | M12: 15.6 | N12: 3.9 | O12: 0.45 | P12: 1.5 | R12: 1.1 | S12: 148.31 | T12: 0.9 | U12: 10.2 | V12: 18.47 | W12: 177.88 | X12: 223.53 | Y12: 45.65 | Z12: 0.01 | AA12: 0 | AB12: 0 | AC12: 0 | AD12: =H12*E12/1000 -> 0 | AE12: =I12*E12/1000 -> 0 | AF12: =ROUND(S12+T12+U12+V12-W12,2) -> 0 | AG12: =ROUND(X12-W12-Y12,2) -> 0
A13: Tega | B13: 2022-23 | C13: May | D13: RM-22-01879ON00-T1 | E13: 29.7 | F13: 24 | G13: 0.71 | J13: 60.87 | K13: 124.1 | L13: 2.17 | M13: 15.72 | N13: 3.9 | O13: 0.45 | P13: 1.5 | R13: 1.1 | S13: 148.94 | T13: 0.9 | U13: 10.2 | V13: 19.05 | W13: 179.08 | X13: 223.53 | Y13: 44.45 | Z13: 0.32 | AA13: 0 | AB13: 0 | AC13: 0 | AD13: =H13*E13/1000 -> 0 | AE13: =I13*E13/1000 -> 0 | AF13: =ROUND(S13+T13+U13+V13-W13,2) -> 0.01 | AG13: =ROUND(X13-W13-Y13,2) -> 0
A14: Tega | B14: 2022-23 | C14: May | D14: RM-22-02782ON00-T1 | E14: 28 | F14: 1 | G14: 0.03 | J14: 68 | K14: 123.3 | L14: 1.94 | M14: 16.59 | N14: 3.9 | O14: 0.45 | P14: 1.5 | R14: 1.1 | S14: 148.78 | T14: 0.9 | U14: 10.2 | V14: 17.87 | W14: 177.75 | X14: 223.53 | Y14: 45.78 | Z14: 0.01 | AA14: 0 | AB14: 0 | AC14: 0 | AD14: =H14*E14/1000 -> 0 | AE14: =I14*E14/1000 -> 0 | AF14: =ROUND(S14+T14+U14+V14-W14,2) -> 0 | AG14: =ROUND(X14-W14-Y14,2) -> 0
A15: Tega | B15: 2022-23 | C15: May | D15: RM-22-02783ON00-T1 | E15: 39.26 | F15: 224 | G15: 8.79 | H15: 21 | I15: 2 | J15: 64.15 | K15: 123.71 | L15: 2.06 | M15: 13.45 | N15: 3.9 | O15: 0.54 | P15: 1.5 | R15: 1.1 | S15: 146.26 | T15: 0.9 | U15: 10.2 | V15: 18.47 | W15: 175.83 | X15: 223.53 | Y15: 47.7 | Z15: 3.33 | AA15: 0.39 | AB15: 0.04 | AC15: 0.43 | AD15: =H15*E15/1000 -> 0.82446 | AE15: =I15*E15/1000 -> 0.07852 | AF15: =ROUND(S15+T15+U15+V15-W15,2) -> 0 | AG15: =ROUND(X15-W15-Y15,2) -> 0
A16: Tega | B16: 2022-23 | C16: May | D16: RM-22-07245ON00-T1 | E16: 28.92 | F16: 32 | G16: 0.93 | H16: 2 | J16: 63.01 | K16: 123.84 | L16: 2.09 | M16: 16.29 | N16: 3.9 | O16: 0.45 | P16: 1.5 | R16: 1.1 | S16: 149.18 | T16: 0.9 | U16: 10.2 | V16: 18.66 | W16: 178.94 | X16: 223.53 | Y16: 44.59 | Z16: 0.36 | AA16: 0.03 | AB16: 0 | AC16: 0.03 | AD16: =H16*E16/1000 -> 0.05784 | AE16: =I16*E16/1000 -> 0 | AF16: =ROUND(S16+T16+U16+V16-W16,2) -> 0 | AG16: =ROUND(X16-W16-Y16,2) -> 0
A17: Tega | B17: 2022-23 | C17: August | D17: RM-22-00593C000-T1 | E17: 34.5 | F17: 142 | G17: 4.9 | J17: 69.03 | K17: 122.74 | L17: 1.91 | M17: 13.2 | N17: 3.9 | O17: 0.54 | P17: 1.5 | R17: 1.1 | S17: 144.89 | T17: 0.9 | U17: 10.74 | V17: 17.74 | W17: 174.28 | X17: 223.53 | Y17: 49.25 | Z17: 2.41 | AA17: 0 | AB17: 0 | AC17: 0 | AD17: =H17*E17/1000 -> 0 | AE17: =I17*E17/1000 -> 0 | AF17: =ROUND(S17+T17+U17+V17-W17,2) -> -0.01 | AG17: =ROUND(X17-W17-Y17,2) -> 0
A18: Tega | B18: 2022-23 | C18: August | D18: RM-22-00591C000-T1 | E18: 26.17 | F18: 42 | G18: 1.1 | H18: 1 | J18: 65.78 | K18: 123.07 | L18: 2.01 | M18: 15.46 | N18: 3.9 | O18: 0.45 | P18: 1.5 | R18: 1.1 | S18: 147.49 | T18: 0.9 | U18: 10.74 | V18: 18.22 | W18: 177.36 | X18: 223.53 | Y18: 46.17 | Z18: 0.48 | AA18: 0.01 | AB18: 0 | AC18: 0.01 | AD18: =H18*E18/1000 -> 0.02617 | AE18: =I18*E18/1000 -> 0 | AF18: =ROUND(S18+T18+U18+V18-W18,2) -> -0.01 | AG18: =ROUND(X18-W18-Y18,2) -> 0
A19: Tega | B19: 2022-23 | C19: August | D19: RM-22-01972AN00-T1 | E19: 50.5 | F19: 60 | G19: 3.03 | H19: 1 | J19: 70.44 | K19: 122.61 | L19: 1.87 | M19: 13.67 | N19: 3.9 | O19: 0.45 | P19: 1.5 | R19: 1.1 | S19: 145.1 | T19: 0.9 | U19: 10.74 | V19: 17.55 | W19: 174.28 | X19: 223.53 | Y19: 49.25 | Z19: 1.44 | AA19: 0.02 | AB19: 0 | AC19: 0.02 | AD19: =H19*E19/1000 -> 0.0505 | AE19: =I19*E19/1000 -> 0 | AF19: =ROUND(S19+T19+U19+V19-W19,2) -> 0.01 | AG19: =ROUND(X19-W19-Y19,2) -> 0
A20: Tega | B20: 2022-23 | C20: August | D20: RM-22-00919AN00-T1 | E20: 22.5 | F20: 70 | G20: 1.58 | J20: 63.96 | K20: 123.27 | L20: 2.06 | M20: 15.66 | N20: 3.9 | O20: 0.45 | P20: 1.5 | R20: 1.1 | S20: 147.95 | T20: 0.9 | U20: 10.74 | V20: 18.52 | W20: 178.1 | X20: 223.53 | Y20: 45.43 | Z20: 0.72 | AA20: 0 | AB20: 0 | AC20: 0 | AD20: =H20*E20/1000 -> 0 | AE20: =I20*E20/1000 -> 0 | AF20: =ROUND(S20+T20+U20+V20-W20,2) -> 0.01 | AG20: =ROUND(X20-W20-Y20,2) -> 0
A21: Tega | B21: 2022-23 | C21: September | D21: RM-22-00593C000-T1 | E21: 34.5 | F21: 4 | G21: 0.14 | H21: 1 | J21: 69.03 | K21: 107.83 | L21: 1.91 | M21: 11.08 | N21: 3.9 | O21: 0.54 | P21: 1.5 | R21: 1.1 | S21: 127.86 | T21: 0.9 | U21: 10.74 | V21: 16.7 | W21: 156.2 | X21: 223.53 | Y21: 67.33 | Z21: 0.06 | AA21: 0.01 | AB21: 0 | AC21: 0.02 | AD21: =H21*E21/1000 -> 0.0345 | AE21: =I21*E21/1000 -> 0 | AF21: =ROUND(S21+T21+U21+V21-W21,2) -> 0 | AG21: =ROUND(X21-W21-Y21,2) -> 0
A22: Tega | B22: 2022-23 | C22: September | D22: RM-22-00591C000-T1 | E22: 26.17 | F22: 4 | G22: 0.1 | H22: 1 | J22: 65.78 | K22: 108.12 | L22: 2.01 | M22: 13.06 | N22: 3.9 | O22: 0.45 | P22: 1.5 | R22: 1.1 | S22: 130.13 | T22: 0.9 | U22: 10.74 | V22: 17.15 | W22: 158.92 | X22: 223.53 | Y22: 64.61 | Z22: 0.04 | AA22: 0.01 | AB22: 0 | AC22: 0.02 | AD22: =H22*E22/1000 -> 0.02617 | AE22: =I22*E22/1000 -> 0 | AF22: =ROUND(S22+T22+U22+V22-W22,2) -> 0 | AG22: =ROUND(X22-W22-Y22,2) -> 0
A23: Tega | B23: 2022-23 | C23: September | D23: RM-22-01972AN00-T1 | E23: 50.5 | F23: 66 | G23: 3.33 | H23: 5 | J23: 70.44 | K23: 107.71 | L23: 1.87 | M23: 11.35 | N23: 3.9 | O23: 0.45 | P23: 1.5 | R23: 1.1 | S23: 127.88 | T23: 0.9 | U23: 10.74 | V23: 16.51 | W23: 156.04 | X23: 223.53 | Y23: 67.49 | Z23: 1.98 | AA23: 0.1 | AB23: 0 | AC23: 0.17 | AD23: =H23*E23/1000 -> 0.2525 | AE23: =I23*E23/1000 -> 0 | AF23: =ROUND(S23+T23+U23+V23-W23,2) -> -0.01 | AG23: =ROUND(X23-W23-Y23,2) -> 0
A24: Tega | B24: 2022-23 | C24: September | D24: RM-22-00919AN00-T1 | E24: 22.5 | F24: 6 | G24: 0.14 | J24: 63.96 | K24: 108.29 | L24: 2.06 | M24: 12.99 | N24: 3.9 | O24: 0.45 | P24: 1.5 | R24: 1.1 | S24: 130.29 | T24: 0.9 | U24: 10.74 | V24: 17.43 | W24: 159.36 | X24: 223.53 | Y24: 64.17 | Z24: 0.09 | AA24: 0 | AB24: 0 | AC24: 0 | AD24: =H24*E24/1000 -> 0 | AE24: =I24*E24/1000 -> 0 | AF24: =ROUND(S24+T24+U24+V24-W24,2) -> 0 | AG24: =ROUND(X24-W24-Y24,2) -> 0
A25: Tega | B25: 2022-23 | C25: December | D25: RM-22-00587E000-T1 | E25: 18.75 | F25: 8 | G25: 0.15 | J25: 59.61 | K25: 147 | L25: 2.21 | M25: 20.46 | N25: 3.9 | O25: 0.45 | P25: 1.5 | R25: 1.1 | S25: 176.63 | T25: 0.9 | U25: 10.74 | V25: 17.17 | W25: 205.44 | X25: 229.13 | Y25: 23.69 | Z25: 0.04 | AA25: 0 | AB25: 0 | AC25: 0 | AD25: =H25*E25/1000 -> 0 | AE25: =I25*E25/1000 -> 0 | AF25: =ROUND(S25+T25+U25+V25-W25,2) -> 0 | AG25: =ROUND(X25-W25-Y25,2) -> 0
A26: Tega | B26: 2022-23 | C26: December | D26: RM-22-00589E000-T1 | E26: 25 | F26: 126 | G26: 3.15 | H26: 6 | J26: 63.85 | K26: 146.39 | L26: 2.07 | M26: 20.53 | N26: 3.9 | O26: 0.45 | P26: 1.5 | R26: 1.1 | S26: 175.94 | T26: 0.9 | U26: 10.74 | V26: 16.5 | W26: 204.08 | X26: 229.13 | Y26: 25.05 | Z26: 0.67 | AA26: 0.08 | AB26: 0 | AC26: 0.04 | AD26: =H26*E26/1000 -> 0.15 | AE26: =I26*E26/1000 -> 0 | AF26: =ROUND(S26+T26+U26+V26-W26,2) -> 0 | AG26: =ROUND(X26-W26-Y26,2) -> 0
A27: Tega | B27: 2022-23 | C27: December | D27: RM-22-01952AN00-T1 | E27: 20.7 | F27: 64 | G27: 1.3248 | J27: 59.04 | K27: 147.09 | L27: 2.24 | M27: 18.87 | N27: 3.9 | O27: 0.45 | P27: 1.5 | R27: 1.1 | S27: 175.14 | T27: 0.9 | U27: 10.74 | V27: 17.27 | W27: 204.05 | X27: 229.13 | Y27: 25.08 | Z27: 0.33 | AA27: 0 | AB27: 0 | AC27: 0 | AD27: =H27*E27/1000 -> 0 | AE27: =I27*E27/1000 -> 0 | AF27: =ROUND(S27+T27+U27+V27-W27,2) -> 0 | AG27: =ROUND(X27-W27-Y27,2) -> 0
A28: Tega | B28: 2022-23 | C28: December | D28: RM-22-00595G000-T1 | E28: 31.66 | F28: 8 | G28: 0.2533 | J28: 61.09 | K28: 146.78 | L28: 2.16 | M28: 15.57 | N28: 3.9 | O28: 0.45 | P28: 1.5 | R28: 1.1 | S28: 171.46 | T28: 0.9 | U28: 10.74 | V28: 16.93 | W28: 200.03 | X28: 244 | Y28: 43.97 | Z28: 0.11 | AA28: 0 | AB28: 0 | AC28: 0 | AD28: =H28*E28/1000 -> 0 | AE28: =I28*E28/1000 -> 0 | AF28: =ROUND(S28+T28+U28+V28-W28,2) -> 0 | AG28: =ROUND(X28-W28-Y28,2) -> 0
A29: Tega | B29: 2022-23 | C29: December | D29: RM-22-03070CN00-T1 | E29: 25 | F29: 6 | G29: 0.15 | J29: 58.82 | K29: 147.13 | L29: 2.24 | M29: 15.28 | N29: 3.9 | O29: 0.45 | P29: 1.5 | R29: 1.1 | S29: 171.6 | T29: 0.9 | U29: 10.74 | V29: 17.3 | W29: 200.54 | X29: 244 | Y29: 43.46 | Z29: 0.07 | AA29: 0 | AB29: 0 | AC29: 0 | AD29: =H29*E29/1000 -> 0 | AE29: =I29*E29/1000 -> 0 | AF29: =ROUND(S29+T29+U29+V29-W29,2) -> 0 | AG29: =ROUND(X29-W29-Y29,2) -> 0
A30: Tega | B30: 2022-23 | C30: December | D30: RM-22-03070CN01-T1 | E30: 34 | F30: 4 | G30: 0.136 | J30: 66.4 | K30: 146.06 | L30: 1.99 | M30: 14.64 | N30: 3.9 | O30: 0.45 | P30: 1.5 | R30: 1.1 | S30: 169.64 | T30: 0.9 | U30: 10.74 | V30: 16.14 | W30: 197.42 | X30: 244 | Y30: 46.58 | Z30: 0.06 | AA30: 0 | AB30: 0 | AC30: 0 | AD30: =H30*E30/1000 -> 0 | AE30: =I30*E30/1000 -> 0 | AF30: =ROUND(S30+T30+U30+V30-W30,2) -> 0 | AG30: =ROUND(X30-W30-Y30,2) -> 0
A31: Tega | B31: 2022-23 | C31: December | D31: RM-22-03070CN02-T1 | E31: 23 | F31: 6 | G31: 0.138 | J31: 61.5 | K31: 146.72 | L31: 2.15 | M31: 15.9 | N31: 3.9 | O31: 0.45 | P31: 1.5 | R31: 1.1 | S31: 171.71 | T31: 0.9 | U31: 10.74 | V31: 16.86 | W31: 200.21 | X31: 244 | Y31: 43.79 | Z31: 0.06 | AA31: 0 | AB31: 0 | AC31: 0 | AD31: =H31*E31/1000 -> 0 | AE31: =I31*E31/1000 -> 0 | AF31: =ROUND(S31+T31+U31+V31-W31,2) -> 0 | AG31: =ROUND(X31-W31-Y31,2) -> 0
A32: Tega | B32: 2022-23 | C32: December | D32: RM-22-06182ON00-T1 | E32: 18 | F32: 1 | G32: 0.018 | J32: 64.17 | K32: 146.35 | L32: 2.06 | M32: 16.68 | N32: 3.9 | O32: 0.45 | P32: 1.5 | R32: 1.1 | S32: 172.04 | T32: 0.9 | U32: 10.74 | V32: 16.46 | W32: 200.13 | X32: 229.13 | Y32: 29 | Z32: 0.01 | AA32: 0 | AB32: 0 | AC32: 0 | AD32: =H32*E32/1000 -> 0 | AE32: =I32*E32/1000 -> 0 | AF32: =ROUND(S32+T32+U32+V32-W32,2) -> 0.01 | AG32: =ROUND(X32-W32-Y32,2) -> 0
A33: Tega | B33: 2022-23 | C33: December | D33: RM-22-01879ON00-T1 | E33: 29.7 | F33: 42 | G33: 1.2474 | J33: 60.87 | K33: 146.81 | L33: 2.17 | M33: 16.73 | N33: 3.9 | O33: 0.45 | P33: 1.5 | R33: 1.1 | S33: 172.66 | T33: 0.9 | U33: 10.74 | V33: 16.96 | W33: 201.26 | X33: 229.13 | Y33: 27.87 | Z33: 0.35 | AA33: 0 | AB33: 0 | AC33: 0 | AD33: =H33*E33/1000 -> 0 | AE33: =I33*E33/1000 -> 0 | AF33: =ROUND(S33+T33+U33+V33-W33,2) -> 0 | AG33: =ROUND(X33-W33-Y33,2) -> 0
A34: Tega | B34: 2022-23 | C34: December | D34: RM-22-02782ON00-T1 | E34: 28 | F34: 3 | G34: 0.084 | H34: 2 | J34: 68 | K34: 145.86 | L34: 1.94 | M34: 17.75 | N34: 3.9 | O34: 0.45 | P34: 1.5 | R34: 1.1 | S34: 172.5 | T34: 0.9 | U34: 10.74 | V34: 15.93 | W34: 200.08 | X34: 229.13 | Y34: 29.05 | Z34: -0.02 | AA34: 0.03 | AB34: 0 | AC34: 0.02 | AD34: =H34*E34/1000 -> 0.056 | AE34: =I34*E34/1000 -> 0 | AF34: =ROUND(S34+T34+U34+V34-W34,2) -> -0.01 | AG34: =ROUND(X34-W34-Y34,2) -> 0
A35: Tega | B35: 2022-23 | C35: December | D35: RM-22-02783ON00-T1 | E35: 39.26 | F35: 216 | G35: 8.4802 | H35: 1 | J35: 64.15 | K35: 146.35 | L35: 2.06 | M35: 14.34 | N35: 3.9 | O35: 0.54 | P35: 1.5 | R35: 1.1 | S35: 169.79 | T35: 0.9 | U35: 10.74 | V35: 16.46 | W35: 197.89 | X35: 229.13 | Y35: 31.24 | Z35: 2.62 | AA35: 0.02 | AB35: 0 | AC35: 0.01 | AD35: =H35*E35/1000 -> 0.03926 | AE35: =I35*E35/1000 -> 0 | AF35: =ROUND(S35+T35+U35+V35-W35,2) -> 0 | AG35: =ROUND(X35-W35-Y35,2) -> 0
A36: Tega | B36: 2022-23 | C36: December | D36: RM-22-07245ON00-T1 | E36: 28.92 | F36: 32 | G36: 0.9254 | J36: 63.01 | K36: 146.51 | L36: 2.09 | M36: 17.36 | N36: 3.9 | O36: 0.45 | P36: 1.5 | R36: 1.1 | S36: 172.91 | T36: 0.9 | U36: 10.74 | V36: 16.63 | W36: 201.18 | X36: 229.13 | Y36: 27.95 | Z36: 0.26 | AA36: 0 | AB36: 0 | AC36: 0 | AD36: =H36*E36/1000 -> 0 | AE36: =I36*E36/1000 -> 0 | AF36: =ROUND(S36+T36+U36+V36-W36,2) -> 0 | AG36: =ROUND(X36-W36-Y36,2) -> 0
A37: Tega | B37: 2022-23 | C37: January | D37: RM-22-00595G000-T1 | E37: 31.66 | F37: 104 | G37: 3.2926 | H37: 10 | J37: 61.09 | K37: 148.44 | L37: 2.16 | M37: 15.57 | N37: 3.9 | O37: 0.45 | P37: 1.5 | R37: 1.1 | S37: 173.12 | T37: 0.9 | U37: 10.74 | V37: 16.93 | W37: 201.69 | X37: 244 | Y37: 42.31 | Z37: 1.1 | AA37: 0.16 | AB37: 0 | AC37: 0.13 | AD37: =H37*E37/1000 -> 0.3166 | AE37: =I37*E37/1000 -> 0 | AF37: =ROUND(S37+T37+U37+V37-W37,2) -> 0 | AG37: =ROUND(X37-W37-Y37,2) -> 0
A38: Tega | B38: 2022-23 | C38: January | D38: RM-22-03070CN00-T1 | E38: 25 | F38: 276 | G38: 6.9 | H38: 37 | J38: 58.82 | K38: 148.79 | L38: 2.24 | M38: 15.28 | N38: 3.9 | O38: 0.45 | P38: 1.5 | R38: 1.1 | S38: 173.26 | T38: 0.9 | U38: 10.74 | V38: 17.3 | W38: 202.21 | X38: 244 | Y38: 41.79 | Z38: 2.04 | AA38: 0.46 | AB38: 0 | AC38: 0.39 | AD38: =H38*E38/1000 -> 0.925 | AE38: =I38*E38/1000 -> 0 | AF38: =ROUND(S38+T38+U38+V38-W38,2) -> -0.01 | AG38: =ROUND(X38-W38-Y38,2) -> 0
A39: Tega | B39: 2022-23 | C39: January | D39: RM-22-03070CN01-T1 | E39: 34 | F39: 52 | G39: 1.768 | H39: 3 | J39: 66.4 | K39: 147.71 | L39: 1.99 | M39: 14.64 | N39: 3.9 | O39: 0.45 | P39: 1.5 | R39: 1.1 | S39: 171.29 | T39: 0.9 | U39: 10.74 | V39: 16.14 | W39: 199.07 | X39: 244 | Y39: 44.93 | Z39: 0.7 | AA39: 0.05 | AB39: 0 | AC39: 0.05 | AD39: =H39*E39/1000 -> 0.102 | AE39: =I39*E39/1000 -> 0 | AF39: =ROUND(S39+T39+U39+V39-W39,2) -> 0 | AG39: =ROUND(X39-W39-Y39,2) -> 0
A40: Tega | B40: 2022-23 | C40: January | D40: RM-22-03070CN02-T1 | E40: 23 | F40: 52 | G40: 1.196 | H40: 5 | J40: 61.5 | K40: 148.38 | L40: 2.15 | M40: 15.9 | N40: 3.9 | O40: 0.45 | P40: 1.5 | R40: 1.1 | S40: 173.37 | T40: 0.9 | U40: 10.74 | V40: 16.86 | W40: 201.87 | X40: 244 | Y40: 42.13 | Z40: 0.4 | AA40: 0.06 | AB40: 0 | AC40: 0.05 | AD40: =H40*E40/1000 -> 0.115 | AE40: =I40*E40/1000 -> 0 | AF40: =ROUND(S40+T40+U40+V40-W40,2) -> 0 | AG40: =ROUND(X40-W40-Y40,2) -> 0
A41: Tega | B41: 2022-23 | C41: February | D41: RM-22-01945AN00-T1 | E41: 28.96 | F41: 8 | G41: 0.2317 | J41: 60.78 | K41: 156 | L41: 2.17 | M41: 13.04 | N41: 3.9 | O41: 0.54 | P41: 1.5 | R41: 1.1 | S41: 178.25 | T41: 0.9 | U41: 10.74 | V41: 16.45 | W41: 206.34 | X41: 283.11 | Y41: 76.77 | Z41: 0.18 | AA41: 0 | AB41: 0 | AC41: 0 | AD41: =H41*E41/1000 -> 0 | AE41: =I41*E41/1000 -> 0 | AF41: =ROUND(S41+T41+U41+V41-W41,2) -> 0 | AG41: =ROUND(X41-W41-Y41,2) -> 0
...

Sheet IN_HO
A1: HO ACCOUNTS INPUTS - ledger items, adjustments and MT statistics (Rs. Lacs)
A2: Financial year label (must match IN_Contrib): | C2: 2026-27
A4: Ref | B4: Item | C4: Apr'26 | D4: May'26 | E4: Jun'26 | F4: Jul'26 | G4: Aug'26 | H4: Sep'26 | I4: Oct'26 | J4: Nov'26 | K4: Dec'26 | L4: Jan'27 | M4: Feb'27 | N4: Mar'27 | O4: Note
B5: GST rate on domestic sales | C5: 0.18 | D5: 0.18 | E5: 0.18 | F5: 0.18 | G5: 0.18 | H5: 0.18 | I5: =C5 -> 0.18 | J5: =C5 -> 0.18 | K5: =C5 -> 0.18 | L5: =C5 -> 0.18 | M5: =C5 -> 0.18 | N5: =C5 -> 0.18 | O5: 18% in all months of Sept'26 MIS
B7: HO ADJUSTMENTS (back-solved from published Sept'26 MIS - HO to document nature)
B8: Material consumed - adjustment (+ increases cost) | C8: -1.8 | D8: 0 | E8: 2.24 | F8: 3 | G8: 2 | H8: 3 | O8: Published less factory PL row 1
B9: (Inc)/Dec in stock - adjustment | C9: 0 | D9: 0 | E9: 0 | F9: 0 | G9: 3 | H9: 0 | O9: Published less (-PL row 6). Aug'26 3.00 to be explained
B10: Power variable - adjustment | C10: 0.14 | D10: 0 | E10: 0.01 | F10: -0.01 | G10: 0 | H10: 0 | O10: Rounding / unallocated
B11: Job-work charges - adjustment (e.g. QC job work not in PL feed) | C11: 0 | D11: 0.13 | E11: 2.07 | F11: 2 | G11: 2.01 | H11: 2 | O11: ~2.00 each month Jun-Sep; Rahaman QC row is blank in factory feed
B12: Selling expenses carved out of Other factory expenses | C12: 0 | D12: 0 | E12: 0 | F12: 0 | G12: 0 | H12: 3.22 | O12: Sep'26 3.22 = transport on sale return. Jun'26 0.29 NOT carved out in published MIS
B13: Pattern income shown under Storage income (reclass) | C13: 0 | D13: 0 | E13: 0 | F13: 0.06 | G13: 0 | H13: 0 | O13: Jul'26 0.06
B15: HO LEDGER ITEMS (not in factory feed)
B16: Administrative Expenses | C16: 3.21 | D16: 4.13 | E16: 4.5 | F16: 7.52 | G16: 6.07 | H16: 7.13
B17: Salary & Wages | C17: 15.91 | D17: 12.37 | E17: 14.85 | F17: 16.85 | G17: 15.87 | H17: 16.61
B18: Deferred Revenue Expenses | C18: 0 | D18: 0 | E18: 0 | F18: 0 | G18: 0 | H18: 0
B19: Other Non-Operating Expenses | C19: 0 | D19: 0 | E19: 0 | F19: 0 | G19: 0 | H19: 0
B20: Depreciation | C20: 0 | D20: 0 | E20: 0 | F20: 0 | G20: 0 | H20: 0
B21: Interest | C21: 0 | D21: 0 | E21: 0 | F21: 0 | G21: 0 | H21: 0
B23: STATISTICS (MT) AND COLLECTIONS
B24: Production (MT) | C24: 33.56 | D24: 84.62 | E24: 83 | F24: 84.62 | G24: 77.44 | H24: 105.48 | O24: Jul'26 identical to May'26 - verify
B25: Despatch (MT) | C25: 50.44 | D25: 36.67 | E25: 106.07 | F25: 36.67 | G25: 94.58 | H25: 89.34 | O25: Jul'26 identical to May'26 - verify
B26: In-house Rejections (MT) | C26: 5.73 | D26: 6.9 | E26: 9.39 | F26: 6.9 | G26: 9.16 | H26: 9.04 | O26: Jul'26 identical to May'26 - verify
B27: Collections (including GST) | C27: 149.75 | D27: 126.8 | E27: 238.95 | F27: 269.64 | G27: 302.91 | H27: 284.24

Sheet CONTRIB_SUM
A1: CONTRIBUTION SUMMARY (formula-driven from IN_Contrib)
A2: Financial year: | B2: =IN_HO!C2 -> 2026-27
A4: Customer-wise contribution (Pouring & rejn.) Rs. Lacs | B4: Apr | C4: May | D4: Jun | E4: Jul | F4: Aug | G4: Sep | H4: Oct | I4: Nov | J4: Dec | K4: Jan | L4: Feb | M4: Mar | N4: Total
A5: Tega | B5: =SUMIFS(IN_Contrib!$Z$4:$Z$2000,IN_Contrib!$A$4:$A$2000,$A5,IN_Contrib!$B$4:$B$2000,$B$2,IN_Contrib!$C$4:$C$2000,"April") -> 8.58 | C5: =SUMIFS(IN_Contrib!$Z$4:$Z$2000,IN_Contrib!$A$4:$A$2000,$A5,IN_Contrib!$B$4:$B$2000,$B$2,IN_Contrib!$C$4:$C$2000,"May") -> 45.44 | D5: =SUMIFS(IN_Contrib!$Z$4:$Z$2000,IN_Contrib!$A$4:$A$2000,$A5,IN_Contrib!$B$4:$B$2000,$B$2,IN_Contrib!$C$4:$C$2000,"June") -> 55.89 | E5: =SUMIFS(IN_Contrib!$Z$4:$Z$2000,IN_Contrib!$A$4:$A$2000,$A5,IN_Contrib!$B$4:$B$2000,$B$2,IN_Contrib!$C$4:$C$2000,"July") -> 33.82 | F5: =SUMIFS(IN_Contrib!$Z$4:$Z$2000,IN_Contrib!$A$4:$A$2000,$A5,IN_Contrib!$B$4:$B$2000,$B$2,IN_Contrib!$C$4:$C$2000,"August") -> 14.57 | G5: =SUMIFS(IN_Contrib!$Z$4:$Z$2000,IN_Contrib!$A$4:$A$2000,$A5,IN_Contrib!$B$4:$B$2000,$B$2,IN_Contrib!$C$4:$C$2000,"September") -> 49.48 | H5: =SUMIFS(IN_Contrib!$Z$4:$Z$2000,IN_Contrib!$A$4:$A$2000,$A5,IN_Contrib!$B$4:$B$2000,$B$2,IN_Contrib!$C$4:$C$2000,"October") -> 0 | I5: =SUMIFS(IN_Contrib!$Z$4:$Z$2000,IN_Contrib!$A$4:$A$2000,$A5,IN_Contrib!$B$4:$B$2000,$B$2,IN_Contrib!$C$4:$C$2000,"November") -> 0 | J5: =SUMIFS(IN_Contrib!$Z$4:$Z$2000,IN_Contrib!$A$4:$A$2000,$A5,IN_Contrib!$B$4:$B$2000,$B$2,IN_Contrib!$C$4:$C$2000,"December") -> 0 | K5: =SUMIFS(IN_Contrib!$Z$4:$Z$2000,IN_Contrib!$A$4:$A$2000,$A5,IN_Contrib!$B$4:$B$2000,$B$2,IN_Contrib!$C$4:$C$2000,"January") -> 0 | L5: =SUMIFS(IN_Contrib!$Z$4:$Z$2000,IN_Contrib!$A$4:$A$2000,$A5,IN_Contrib!$B$4:$B$2000,$B$2,IN_Contrib!$C$4:$C$2000,"February") -> 0 | M5: =SUMIFS(IN_Contrib!$Z$4:$Z$2000,IN_Contrib!$A$4:$A$2000,$A5,IN_Contrib!$B$4:$B$2000,$B$2,IN_Contrib!$C$4:$C$2000,"March") -> 0 | N5: =SUM(B5:M5) -> 207.78
A6: Thejo Engineering | B6: =SUMIFS(IN_Contrib!$Z$4:$Z$2000,IN_Contrib!$A$4:$A$2000,$A6,IN_Contrib!$B$4:$B$2000,$B$2,IN_Contrib!$C$4:$C$2000,"April") -> 12.38 | C6: =SUMIFS(IN_Contrib!$Z$4:$Z$2000,IN_Contrib!$A$4:$A$2000,$A6,IN_Contrib!$B$4:$B$2000,$B$2,IN_Contrib!$C$4:$C$2000,"May") -> 1.39 | D6: =SUMIFS(IN_Contrib!$Z$4:$Z$2000,IN_Contrib!$A$4:$A$2000,$A6,IN_Contrib!$B$4:$B$2000,$B$2,IN_Contrib!$C$4:$C$2000,"June") -> 0 | E6: =SUMIFS(IN_Contrib!$Z$4:$Z$2000,IN_Contrib!$A$4:$A$2000,$A6,IN_Contrib!$B$4:$B$2000,$B$2,IN_Contrib!$C$4:$C$2000,"July") -> 23.23 | F6: =SUMIFS(IN_Contrib!$Z$4:$Z$2000,IN_Contrib!$A$4:$A$2000,$A6,IN_Contrib!$B$4:$B$2000,$B$2,IN_Contrib!$C$4:$C$2000,"August") -> 33.41 | G6: =SUMIFS(IN_Contrib!$Z$4:$Z$2000,IN_Contrib!$A$4:$A$2000,$A6,IN_Contrib!$B$4:$B$2000,$B$2,IN_Contrib!$C$4:$C$2000,"September") -> 22.54 | H6: =SUMIFS(IN_Contrib!$Z$4:$Z$2000,IN_Contrib!$A$4:$A$2000,$A6,IN_Contrib!$B$4:$B$2000,$B$2,IN_Contrib!$C$4:$C$2000,"October") -> 0 | I6: =SUMIFS(IN_Contrib!$Z$4:$Z$2000,IN_Contrib!$A$4:$A$2000,$A6,IN_Contrib!$B$4:$B$2000,$B$2,IN_Contrib!$C$4:$C$2000,"November") -> 0 | J6: =SUMIFS(IN_Contrib!$Z$4:$Z$2000,IN_Contrib!$A$4:$A$2000,$A6,IN_Contrib!$B$4:$B$2000,$B$2,IN_Contrib!$C$4:$C$2000,"December") -> 0 | K6: =SUMIFS(IN_Contrib!$Z$4:$Z$2000,IN_Contrib!$A$4:$A$2000,$A6,IN_Contrib!$B$4:$B$2000,$B$2,IN_Contrib!$C$4:$C$2000,"January") -> 0 | L6: =SUMIFS(IN_Contrib!$Z$4:$Z$2000,IN_Contrib!$A$4:$A$2000,$A6,IN_Contrib!$B$4:$B$2000,$B$2,IN_Contrib!$C$4:$C$2000,"February") -> 0 | M6: =SUMIFS(IN_Contrib!$Z$4:$Z$2000,IN_Contrib!$A$4:$A$2000,$A6,IN_Contrib!$B$4:$B$2000,$B$2,IN_Contrib!$C$4:$C$2000,"March") -> 0 | N6: =SUM(B6:M6) -> 92.95
A7: ESCORT(Main Body) Rev.3 | B7: =SUMIFS(IN_Contrib!$Z$4:$Z$2000,IN_Contrib!$A$4:$A$2000,$A7,IN_Contrib!$B$4:$B$2000,$B$2,IN_Contrib!$C$4:$C$2000,"April") -> 0 | C7: =SUMIFS(IN_Contrib!$Z$4:$Z$2000,IN_Contrib!$A$4:$A$2000,$A7,IN_Contrib!$B$4:$B$2000,$B$2,IN_Contrib!$C$4:$C$2000,"May") -> 0 | D7: =SUMIFS(IN_Contrib!$Z$4:$Z$2000,IN_Contrib!$A$4:$A$2000,$A7,IN_Contrib!$B$4:$B$2000,$B$2,IN_Contrib!$C$4:$C$2000,"June") -> 0 | E7: =SUMIFS(IN_Contrib!$Z$4:$Z$2000,IN_Contrib!$A$4:$A$2000,$A7,IN_Contrib!$B$4:$B$2000,$B$2,IN_Contrib!$C$4:$C$2000,"July") -> 0 | F7: =SUMIFS(IN_Contrib!$Z$4:$Z$2000,IN_Contrib!$A$4:$A$2000,$A7,IN_Contrib!$B$4:$B$2000,$B$2,IN_Contrib!$C$4:$C$2000,"August") -> 0 | G7: =SUMIFS(IN_Contrib!$Z$4:$Z$2000,IN_Contrib!$A$4:$A$2000,$A7,IN_Contrib!$B$4:$B$2000,$B$2,IN_Contrib!$C$4:$C$2000,"September") -> 0 | H7: =SUMIFS(IN_Contrib!$Z$4:$Z$2000,IN_Contrib!$A$4:$A$2000,$A7,IN_Contrib!$B$4:$B$2000,$B$2,IN_Contrib!$C$4:$C$2000,"October") -> 0 | I7: =SUMIFS(IN_Contrib!$Z$4:$Z$2000,IN_Contrib!$A$4:$A$2000,$A7,IN_Contrib!$B$4:$B$2000,$B$2,IN_Contrib!$C$4:$C$2000,"November") -> 0 | J7: =SUMIFS(IN_Contrib!$Z$4:$Z$2000,IN_Contrib!$A$4:$A$2000,$A7,IN_Contrib!$B$4:$B$2000,$B$2,IN_Contrib!$C$4:$C$2000,"December") -> 0 | K7: =SUMIFS(IN_Contrib!$Z$4:$Z$2000,IN_Contrib!$A$4:$A$2000,$A7,IN_Contrib!$B$4:$B$2000,$B$2,IN_Contrib!$C$4:$C$2000,"January") -> 0 | L7: =SUMIFS(IN_Contrib!$Z$4:$Z$2000,IN_Contrib!$A$4:$A$2000,$A7,IN_Contrib!$B$4:$B$2000,$B$2,IN_Contrib!$C$4:$C$2000,"February") -> 0 | M7: =SUMIFS(IN_Contrib!$Z$4:$Z$2000,IN_Contrib!$A$4:$A$2000,$A7,IN_Contrib!$B$4:$B$2000,$B$2,IN_Contrib!$C$4:$C$2000,"March") -> 0 | N7: =SUM(B7:M7) -> 0
A8: ESCORT (Knuckle) | B8: =SUMIFS(IN_Contrib!$Z$4:$Z$2000,IN_Contrib!$A$4:$A$2000,$A8,IN_Contrib!$B$4:$B$2000,$B$2,IN_Contrib!$C$4:$C$2000,"April") -> 0 | C8: =SUMIFS(IN_Contrib!$Z$4:$Z$2000,IN_Contrib!$A$4:$A$2000,$A8,IN_Contrib!$B$4:$B$2000,$B$2,IN_Contrib!$C$4:$C$2000,"May") -> 0 | D8: =SUMIFS(IN_Contrib!$Z$4:$Z$2000,IN_Contrib!$A$4:$A$2000,$A8,IN_Contrib!$B$4:$B$2000,$B$2,IN_Contrib!$C$4:$C$2000,"June") -> 0 | E8: =SUMIFS(IN_Contrib!$Z$4:$Z$2000,IN_Contrib!$A$4:$A$2000,$A8,IN_Contrib!$B$4:$B$2000,$B$2,IN_Contrib!$C$4:$C$2000,"July") -> 0 | F8: =SUMIFS(IN_Contrib!$Z$4:$Z$2000,IN_Contrib!$A$4:$A$2000,$A8,IN_Contrib!$B$4:$B$2000,$B$2,IN_Contrib!$C$4:$C$2000,"August") -> 0 | G8: =SUMIFS(IN_Contrib!$Z$4:$Z$2000,IN_Contrib!$A$4:$A$2000,$A8,IN_Contrib!$B$4:$B$2000,$B$2,IN_Contrib!$C$4:$C$2000,"September") -> 0 | H8: =SUMIFS(IN_Contrib!$Z$4:$Z$2000,IN_Contrib!$A$4:$A$2000,$A8,IN_Contrib!$B$4:$B$2000,$B$2,IN_Contrib!$C$4:$C$2000,"October") -> 0 | I8: =SUMIFS(IN_Contrib!$Z$4:$Z$2000,IN_Contrib!$A$4:$A$2000,$A8,IN_Contrib!$B$4:$B$2000,$B$2,IN_Contrib!$C$4:$C$2000,"November") -> 0 | J8: =SUMIFS(IN_Contrib!$Z$4:$Z$2000,IN_Contrib!$A$4:$A$2000,$A8,IN_Contrib!$B$4:$B$2000,$B$2,IN_Contrib!$C$4:$C$2000,"December") -> 0 | K8: =SUMIFS(IN_Contrib!$Z$4:$Z$2000,IN_Contrib!$A$4:$A$2000,$A8,IN_Contrib!$B$4:$B$2000,$B$2,IN_Contrib!$C$4:$C$2000,"January") -> 0 | L8: =SUMIFS(IN_Contrib!$Z$4:$Z$2000,IN_Contrib!$A$4:$A$2000,$A8,IN_Contrib!$B$4:$B$2000,$B$2,IN_Contrib!$C$4:$C$2000,"February") -> 0 | M8: =SUMIFS(IN_Contrib!$Z$4:$Z$2000,IN_Contrib!$A$4:$A$2000,$A8,IN_Contrib!$B$4:$B$2000,$B$2,IN_Contrib!$C$4:$C$2000,"March") -> 0 | N8: =SUM(B8:M8) -> 0
A9: ESCORT (Lock Casting) | B9: =SUMIFS(IN_Contrib!$Z$4:$Z$2000,IN_Contrib!$A$4:$A$2000,$A9,IN_Contrib!$B$4:$B$2000,$B$2,IN_Contrib!$C$4:$C$2000,"April") -> 0 | C9: =SUMIFS(IN_Contrib!$Z$4:$Z$2000,IN_Contrib!$A$4:$A$2000,$A9,IN_Contrib!$B$4:$B$2000,$B$2,IN_Contrib!$C$4:$C$2000,"May") -> 0 | D9: =SUMIFS(IN_Contrib!$Z$4:$Z$2000,IN_Contrib!$A$4:$A$2000,$A9,IN_Contrib!$B$4:$B$2000,$B$2,IN_Contrib!$C$4:$C$2000,"June") -> 0 | E9: =SUMIFS(IN_Contrib!$Z$4:$Z$2000,IN_Contrib!$A$4:$A$2000,$A9,IN_Contrib!$B$4:$B$2000,$B$2,IN_Contrib!$C$4:$C$2000,"July") -> 0 | F9: =SUMIFS(IN_Contrib!$Z$4:$Z$2000,IN_Contrib!$A$4:$A$2000,$A9,IN_Contrib!$B$4:$B$2000,$B$2,IN_Contrib!$C$4:$C$2000,"August") -> 0 | G9: =SUMIFS(IN_Contrib!$Z$4:$Z$2000,IN_Contrib!$A$4:$A$2000,$A9,IN_Contrib!$B$4:$B$2000,$B$2,IN_Contrib!$C$4:$C$2000,"September") -> 0 | H9: =SUMIFS(IN_Contrib!$Z$4:$Z$2000,IN_Contrib!$A$4:$A$2000,$A9,IN_Contrib!$B$4:$B$2000,$B$2,IN_Contrib!$C$4:$C$2000,"October") -> 0 | I9: =SUMIFS(IN_Contrib!$Z$4:$Z$2000,IN_Contrib!$A$4:$A$2000,$A9,IN_Contrib!$B$4:$B$2000,$B$2,IN_Contrib!$C$4:$C$2000,"November") -> 0 | J9: =SUMIFS(IN_Contrib!$Z$4:$Z$2000,IN_Contrib!$A$4:$A$2000,$A9,IN_Contrib!$B$4:$B$2000,$B$2,IN_Contrib!$C$4:$C$2000,"December") -> 0 | K9: =SUMIFS(IN_Contrib!$Z$4:$Z$2000,IN_Contrib!$A$4:$A$2000,$A9,IN_Contrib!$B$4:$B$2000,$B$2,IN_Contrib!$C$4:$C$2000,"January") -> 0 | L9: =SUMIFS(IN_Contrib!$Z$4:$Z$2000,IN_Contrib!$A$4:$A$2000,$A9,IN_Contrib!$B$4:$B$2000,$B$2,IN_Contrib!$C$4:$C$2000,"February") -> 0 | M9: =SUMIFS(IN_Contrib!$Z$4:$Z$2000,IN_Contrib!$A$4:$A$2000,$A9,IN_Contrib!$B$4:$B$2000,$B$2,IN_Contrib!$C$4:$C$2000,"March") -> 0 | N9: =SUM(B9:M9) -> 0
A10: ESCORT (Autometic Coupler) | B10: =SUMIFS(IN_Contrib!$Z$4:$Z$2000,IN_Contrib!$A$4:$A$2000,$A10,IN_Contrib!$B$4:$B$2000,$B$2,IN_Contrib!$C$4:$C$2000,"April") -> 0 | C10: =SUMIFS(IN_Contrib!$Z$4:$Z$2000,IN_Contrib!$A$4:$A$2000,$A10,IN_Contrib!$B$4:$B$2000,$B$2,IN_Contrib!$C$4:$C$2000,"May") -> 0 | D10: =SUMIFS(IN_Contrib!$Z$4:$Z$2000,IN_Contrib!$A$4:$A$2000,$A10,IN_Contrib!$B$4:$B$2000,$B$2,IN_Contrib!$C$4:$C$2000,"June") -> 0 | E10: =SUMIFS(IN_Contrib!$Z$4:$Z$2000,IN_Contrib!$A$4:$A$2000,$A10,IN_Contrib!$B$4:$B$2000,$B$2,IN_Contrib!$C$4:$C$2000,"July") -> 0 | F10: =SUMIFS(IN_Contrib!$Z$4:$Z$2000,IN_Contrib!$A$4:$A$2000,$A10,IN_Contrib!$B$4:$B$2000,$B$2,IN_Contrib!$C$4:$C$2000,"August") -> 0 | G10: =SUMIFS(IN_Contrib!$Z$4:$Z$2000,IN_Contrib!$A$4:$A$2000,$A10,IN_Contrib!$B$4:$B$2000,$B$2,IN_Contrib!$C$4:$C$2000,"September") -> 0 | H10: =SUMIFS(IN_Contrib!$Z$4:$Z$2000,IN_Contrib!$A$4:$A$2000,$A10,IN_Contrib!$B$4:$B$2000,$B$2,IN_Contrib!$C$4:$C$2000,"October") -> 0 | I10: =SUMIFS(IN_Contrib!$Z$4:$Z$2000,IN_Contrib!$A$4:$A$2000,$A10,IN_Contrib!$B$4:$B$2000,$B$2,IN_Contrib!$C$4:$C$2000,"November") -> 0 | J10: =SUMIFS(IN_Contrib!$Z$4:$Z$2000,IN_Contrib!$A$4:$A$2000,$A10,IN_Contrib!$B$4:$B$2000,$B$2,IN_Contrib!$C$4:$C$2000,"December") -> 0 | K10: =SUMIFS(IN_Contrib!$Z$4:$Z$2000,IN_Contrib!$A$4:$A$2000,$A10,IN_Contrib!$B$4:$B$2000,$B$2,IN_Contrib!$C$4:$C$2000,"January") -> 0 | L10: =SUMIFS(IN_Contrib!$Z$4:$Z$2000,IN_Contrib!$A$4:$A$2000,$A10,IN_Contrib!$B$4:$B$2000,$B$2,IN_Contrib!$C$4:$C$2000,"February") -> 0 | M10: =SUMIFS(IN_Contrib!$Z$4:$Z$2000,IN_Contrib!$A$4:$A$2000,$A10,IN_Contrib!$B$4:$B$2000,$B$2,IN_Contrib!$C$4:$C$2000,"March") -> 0 | N10: =SUM(B10:M10) -> 0
A11: ESCORT (Fork Eye) | B11: =SUMIFS(IN_Contrib!$Z$4:$Z$2000,IN_Contrib!$A$4:$A$2000,$A11,IN_Contrib!$B$4:$B$2000,$B$2,IN_Contrib!$C$4:$C$2000,"April") -> 0 | C11: =SUMIFS(IN_Contrib!$Z$4:$Z$2000,IN_Contrib!$A$4:$A$2000,$A11,IN_Contrib!$B$4:$B$2000,$B$2,IN_Contrib!$C$4:$C$2000,"May") -> 0 | D11: =SUMIFS(IN_Contrib!$Z$4:$Z$2000,IN_Contrib!$A$4:$A$2000,$A11,IN_Contrib!$B$4:$B$2000,$B$2,IN_Contrib!$C$4:$C$2000,"June") -> 0 | E11: =SUMIFS(IN_Contrib!$Z$4:$Z$2000,IN_Contrib!$A$4:$A$2000,$A11,IN_Contrib!$B$4:$B$2000,$B$2,IN_Contrib!$C$4:$C$2000,"July") -> 0 | F11: =SUMIFS(IN_Contrib!$Z$4:$Z$2000,IN_Contrib!$A$4:$A$2000,$A11,IN_Contrib!$B$4:$B$2000,$B$2,IN_Contrib!$C$4:$C$2000,"August") -> 0 | G11: =SUMIFS(IN_Contrib!$Z$4:$Z$2000,IN_Contrib!$A$4:$A$2000,$A11,IN_Contrib!$B$4:$B$2000,$B$2,IN_Contrib!$C$4:$C$2000,"September") -> 0 | H11: =SUMIFS(IN_Contrib!$Z$4:$Z$2000,IN_Contrib!$A$4:$A$2000,$A11,IN_Contrib!$B$4:$B$2000,$B$2,IN_Contrib!$C$4:$C$2000,"October") -> 0 | I11: =SUMIFS(IN_Contrib!$Z$4:$Z$2000,IN_Contrib!$A$4:$A$2000,$A11,IN_Contrib!$B$4:$B$2000,$B$2,IN_Contrib!$C$4:$C$2000,"November") -> 0 | J11: =SUMIFS(IN_Contrib!$Z$4:$Z$2000,IN_Contrib!$A$4:$A$2000,$A11,IN_Contrib!$B$4:$B$2000,$B$2,IN_Contrib!$C$4:$C$2000,"December") -> 0 | K11: =SUMIFS(IN_Contrib!$Z$4:$Z$2000,IN_Contrib!$A$4:$A$2000,$A11,IN_Contrib!$B$4:$B$2000,$B$2,IN_Contrib!$C$4:$C$2000,"January") -> 0 | L11: =SUMIFS(IN_Contrib!$Z$4:$Z$2000,IN_Contrib!$A$4:$A$2000,$A11,IN_Contrib!$B$4:$B$2000,$B$2,IN_Contrib!$C$4:$C$2000,"February") -> 0 | M11: =SUMIFS(IN_Contrib!$Z$4:$Z$2000,IN_Contrib!$A$4:$A$2000,$A11,IN_Contrib!$B$4:$B$2000,$B$2,IN_Contrib!$C$4:$C$2000,"March") -> 0 | N11: =SUM(B11:M11) -> 0
A12: BEML | B12: =SUMIFS(IN_Contrib!$Z$4:$Z$2000,IN_Contrib!$A$4:$A$2000,$A12,IN_Contrib!$B$4:$B$2000,$B$2,IN_Contrib!$C$4:$C$2000,"April") -> 0 | C12: =SUMIFS(IN_Contrib!$Z$4:$Z$2000,IN_Contrib!$A$4:$A$2000,$A12,IN_Contrib!$B$4:$B$2000,$B$2,IN_Contrib!$C$4:$C$2000,"May") -> 0 | D12: =SUMIFS(IN_Contrib!$Z$4:$Z$2000,IN_Contrib!$A$4:$A$2000,$A12,IN_Contrib!$B$4:$B$2000,$B$2,IN_Contrib!$C$4:$C$2000,"June") -> 0 | E12: =SUMIFS(IN_Contrib!$Z$4:$Z$2000,IN_Contrib!$A$4:$A$2000,$A12,IN_Contrib!$B$4:$B$2000,$B$2,IN_Contrib!$C$4:$C$2000,"July") -> 0 | F12: =SUMIFS(IN_Contrib!$Z$4:$Z$2000,IN_Contrib!$A$4:$A$2000,$A12,IN_Contrib!$B$4:$B$2000,$B$2,IN_Contrib!$C$4:$C$2000,"August") -> 0 | G12: =SUMIFS(IN_Contrib!$Z$4:$Z$2000,IN_Contrib!$A$4:$A$2000,$A12,IN_Contrib!$B$4:$B$2000,$B$2,IN_Contrib!$C$4:$C$2000,"September") -> 0 | H12: =SUMIFS(IN_Contrib!$Z$4:$Z$2000,IN_Contrib!$A$4:$A$2000,$A12,IN_Contrib!$B$4:$B$2000,$B$2,IN_Contrib!$C$4:$C$2000,"October") -> 0 | I12: =SUMIFS(IN_Contrib!$Z$4:$Z$2000,IN_Contrib!$A$4:$A$2000,$A12,IN_Contrib!$B$4:$B$2000,$B$2,IN_Contrib!$C$4:$C$2000,"November") -> 0 | J12: =SUMIFS(IN_Contrib!$Z$4:$Z$2000,IN_Contrib!$A$4:$A$2000,$A12,IN_Contrib!$B$4:$B$2000,$B$2,IN_Contrib!$C$4:$C$2000,"December") -> 0 | K12: =SUMIFS(IN_Contrib!$Z$4:$Z$2000,IN_Contrib!$A$4:$A$2000,$A12,IN_Contrib!$B$4:$B$2000,$B$2,IN_Contrib!$C$4:$C$2000,"January") -> 0 | L12: =SUMIFS(IN_Contrib!$Z$4:$Z$2000,IN_Contrib!$A$4:$A$2000,$A12,IN_Contrib!$B$4:$B$2000,$B$2,IN_Contrib!$C$4:$C$2000,"February") -> 0 | M12: =SUMIFS(IN_Contrib!$Z$4:$Z$2000,IN_Contrib!$A$4:$A$2000,$A12,IN_Contrib!$B$4:$B$2000,$B$2,IN_Contrib!$C$4:$C$2000,"March") -> 0 | N12: =SUM(B12:M12) -> 0
A13: Uchimura India | B13: =SUMIFS(IN_Contrib!$Z$4:$Z$2000,IN_Contrib!$A$4:$A$2000,$A13,IN_Contrib!$B$4:$B$2000,$B$2,IN_Contrib!$C$4:$C$2000,"April") -> 0 | C13: =SUMIFS(IN_Contrib!$Z$4:$Z$2000,IN_Contrib!$A$4:$A$2000,$A13,IN_Contrib!$B$4:$B$2000,$B$2,IN_Contrib!$C$4:$C$2000,"May") -> 0 | D13: =SUMIFS(IN_Contrib!$Z$4:$Z$2000,IN_Contrib!$A$4:$A$2000,$A13,IN_Contrib!$B$4:$B$2000,$B$2,IN_Contrib!$C$4:$C$2000,"June") -> 0 | E13: =SUMIFS(IN_Contrib!$Z$4:$Z$2000,IN_Contrib!$A$4:$A$2000,$A13,IN_Contrib!$B$4:$B$2000,$B$2,IN_Contrib!$C$4:$C$2000,"July") -> 0 | F13: =SUMIFS(IN_Contrib!$Z$4:$Z$2000,IN_Contrib!$A$4:$A$2000,$A13,IN_Contrib!$B$4:$B$2000,$B$2,IN_Contrib!$C$4:$C$2000,"August") -> 0 | G13: =SUMIFS(IN_Contrib!$Z$4:$Z$2000,IN_Contrib!$A$4:$A$2000,$A13,IN_Contrib!$B$4:$B$2000,$B$2,IN_Contrib!$C$4:$C$2000,"September") -> 0 | H13: =SUMIFS(IN_Contrib!$Z$4:$Z$2000,IN_Contrib!$A$4:$A$2000,$A13,IN_Contrib!$B$4:$B$2000,$B$2,IN_Contrib!$C$4:$C$2000,"October") -> 0 | I13: =SUMIFS(IN_Contrib!$Z$4:$Z$2000,IN_Contrib!$A$4:$A$2000,$A13,IN_Contrib!$B$4:$B$2000,$B$2,IN_Contrib!$C$4:$C$2000,"November") -> 0 | J13: =SUMIFS(IN_Contrib!$Z$4:$Z$2000,IN_Contrib!$A$4:$A$2000,$A13,IN_Contrib!$B$4:$B$2000,$B$2,IN_Contrib!$C$4:$C$2000,"December") -> 0 | K13: =SUMIFS(IN_Contrib!$Z$4:$Z$2000,IN_Contrib!$A$4:$A$2000,$A13,IN_Contrib!$B$4:$B$2000,$B$2,IN_Contrib!$C$4:$C$2000,"January") -> 0 | L13: =SUMIFS(IN_Contrib!$Z$4:$Z$2000,IN_Contrib!$A$4:$A$2000,$A13,IN_Contrib!$B$4:$B$2000,$B$2,IN_Contrib!$C$4:$C$2000,"February") -> 0 | M13: =SUMIFS(IN_Contrib!$Z$4:$Z$2000,IN_Contrib!$A$4:$A$2000,$A13,IN_Contrib!$B$4:$B$2000,$B$2,IN_Contrib!$C$4:$C$2000,"March") -> 0 | N13: =SUM(B13:M13) -> 0
